Workbook

Sheet Resumen
A1: #VALUE! | B1: BARRIO SOLIDARIO
B2: Resumen de gestión de cambios
A5: Indicador | B5: Resultado | D5: Etapa | E5: Responsable principal | F5: Resultado esperado | H5: Identificación del documento
A6: Total de solicitudes | B6: =COUNTIF('Registro de cambios'!B13:B112,"<>") -> 0 | D6: 1. Registro | E6: Solicitante | F6: Solicitud completa y trazable | H6: Código | I6: DOC-10
A7: En análisis | B7: =COUNTIF('Registro de cambios'!Y13:Y112,"En análisis") -> 0 | D7: 2. Análisis | E7: Analista funcional/técnico | F7: Impactos, riesgo y esfuerzo estimados | H7: Documento | I7: Formato de Gestión de Cambios
A8: Pendientes de aprobación | B8: =COUNTIF('Registro de cambios'!Y13:Y112,"Pendiente de aprobación") -> 0 | D8: 3. Decisión | E8: Product Owner / aprobador | F8: Decisión y condiciones documentadas | H8: Proyecto | I8: Barrio Solidario
A9: Aprobadas | B9: =COUNTIF('Registro de cambios'!Y13:Y112,"Aprobado") -> 0 | D9: 4. Planificación | E9: Scrum Master / equipo | F9: Fecha, responsable y versión objetivo | H9: Aplicación | I9: Software y documentación
A10: En implementación | B10: =COUNTIF('Registro de cambios'!Y13:Y112,"En implementación") -> 0 | D10: 5. Implementación | E10: Responsable asignado | F10: Cambio aplicado y evidencia registrada | H10: Versión vigente | I10: 1.0.0
A11: En validación | B11: =COUNTIF('Registro de cambios'!Y13:Y112,"En validación") -> 0 | D11: 6. Validación | E11: Calidad / Product Owner | F11: Criterios y pruebas conformes | H11: Estado | I11: En elaboración
A12: Cerradas | B12: =COUNTIF('Registro de cambios'!Y13:Y112,"Cerrado") -> 0 | D12: 7. Cierre | E12: Aprobador | F12: Versión actualizada y lecciones registradas | H12: Fecha de creación | I12: 14/09/2026
A13: Rechazadas | B13: =COUNTIF('Registro de cambios'!Y13:Y112,"Rechazado") -> 0 | H13: Propietario | I13: Víctor Tello Bravo – Product Owner
A14: Vencidas abiertas | B14: =COUNTIFS('Registro de cambios'!Z13:Z112,"<"&TODAY(),'Registro de cambios'!Z13:Z112,"<>",'Registro de cambios'!Y13:Y112,"<>Cerrado",'Registro de cambios'!Y13:Y112,"<>Cancelado",'Registro de cambios'!Y13:Y112,"<>Rechazado") -> 0 | H14: Consolidación | I14: Alex Mendoza Morante – Scrum Master
H15: Revisión técnica | I15: Kevin Carriel Bonoso – Arquitecto de software
H16: Revisión de calidad | I16: Luis Rodríguez Barrera – Calidad y seguridad
H17: Nivel de acceso | I17: Uso académico
A18: Control de versiones
A19: Versión | B19: Fecha | C19: Descripción | D19: Responsable | E19: Revisor | F19: Estado | H19: Nombre | I19: Rol | J19: Acción | K19: Estado
A20: 0.1.0 | B20: 14/09/2026 | C20: Definición del flujo y campos | D20: Víctor Tello Bravo | E20: Alex Mendoza Morante | F20: Completado | H20: Víctor Tello Bravo | I20: Product Owner | J20: Validación del proceso y decisiones | L20: Revisado
A21: 0.2.0 | B21: 14/09/2026 | C21: Controles de impacto, riesgo y validación | D21: Kevin Carriel Bonoso / Luis Rodríguez Barrera | E21: Víctor Tello Bravo | F21: Completado | H21: Alex Mendoza Morante | I21: Scrum Master | J21: Control, trazabilidad y consolidación | L21: Revisado
A22: 0.9.0 | B22: 14/09/2026 | C22: Revisión integral del formato | D22: Alex Mendoza Morante | E22: Equipo del proyecto | F22: Revisado | H22: Kevin Carriel Bonoso | I22: Arquitecto de software | J22: Análisis técnico y de arquitectura | L22: Revisado
A23: 1.0.0 | B23: 14/09/2026 | C23: Versión consolidada para Sprint 3 | D23: Alex Mendoza Morante | E23: Ing. Victoria García Velásquez | F23: En elaboración | H23: Luis Rodríguez Barrera | I23: Calidad y seguridad | J23: Validación, riesgos y evidencias | L23: Revisado
H24: Ing. Victoria García Velásquez | I24: Patrocinadora académica | J24: Revisión académica y aprobación | L24: Pendiente

Sheet Registro de cambios
A1: #VALUE! | C1: BARRIO SOLIDARIO
C2: Registro y seguimiento de solicitudes de cambio
A3: Código: DOC-10 | E3: Versión: 1.0.0 | I3: Estado: En elaboración | M3: Actualización: 14/09/2026 | R3: Proyecto: Barrio Solidario | W3: Uso: Software y documentación
A4: Propietario: Víctor Tello Bravo – Product Owner | G4: Consolidación: Alex Mendoza Morante – Scrum Master | M4: Revisión técnica: Kevin Carriel Bonoso | S4: Revisión de calidad: Luis Rodríguez Barrera | Y4: Aprobación académica: Ing. Victoria García Velásquez
A6: CONTROL GENERAL DE CAMBIOS
A7: Total | E7: Pendientes de aprobación | I7: Aprobados | M7: En implementación | Q7: Cerrados | U7: Rechazados | Y7: Vencidos abiertos | AC7: Estado del control
A8: =COUNTIF(B13:B112,"<>") -> 0 | E8: =COUNTIF(Y13:Y112,"Pendiente de aprobación") -> 0 | I8: =COUNTIF(Y13:Y112,"Aprobado") -> 0 | M8: =COUNTIF(Y13:Y112,"En implementación") -> 0 | Q8: =COUNTIF(Y13:Y112,"Cerrado") -> 0 | U8: =COUNTIF(Y13:Y112,"Rechazado") -> 0 | Y8: =COUNTIFS(Z13:Z112,"<"&TODAY(),Z13:Z112,"<>",Y13:Y112,"<>Cerrado",Y13:Y112,"<>Cancelado",Y13:Y112,"<>Rechazado") -> 0 | AC8: =IF(Y8>0,"REQUIERE ATENCIÓN",IF(E8>0,"PENDIENTE DE DECISIÓN","AL DÍA")) -> AL DÍA
A10: Flujo recomendado: registrar → analizar impacto y riesgo → decidir → planificar → implementar → validar → cerrar. Los cambios rechazados o cancelados conservan su trazabilidad.
A12: Código | B12: Fecha de solicitud | C12: Tipo de cambio | D12: Origen | E12: Título del cambio | F12: Descripción y justificación | G12: Elemento afectado | H12: Versión actual | I12: Prioridad | J12: Urgencia | K12: Impacto alcance | L12: Impacto cronograma | M12: Impacto costo | N12: Impacto calidad | O12: Impacto seguridad | P12: Probabilidad | Q12: Impacto del riesgo | R12: Exposición | S12: Nivel de riesgo | T12: Esfuerzo estimado (h) | U12: Solicitante | V12: Analista de impacto | W12: Aprobador | X12: Decisión | Y12: Estado | Z12: Fecha objetivo | AA12: Fecha implementación | AB12: Resultado de validación | AC12: Validador | AD12: Evidencia / enlace | AE12: Versión resultante | AF12: Observaciones
A13: =IF(B13="","","SC-"&TEXT(ROW()-12,"000")) | R13: =IF(OR(P13="",Q13=""),"",P13*Q13) | S13: =IF(R13="","",IF(R13>=17,"Crítico",IF(R13>=10,"Alto",IF(R13>=5,"Medio","Bajo"))))
A14: =IF(B14="","","SC-"&TEXT(ROW()-12,"000")) | R14: =IF(OR(P14="",Q14=""),"",P14*Q14) | S14: =IF(R14="","",IF(R14>=17,"Crítico",IF(R14>=10,"Alto",IF(R14>=5,"Medio","Bajo"))))
A15: =IF(B15="","","SC-"&TEXT(ROW()-12,"000")) | R15: =IF(OR(P15="",Q15=""),"",P15*Q15) | S15: =IF(R15="","",IF(R15>=17,"Crítico",IF(R15>=10,"Alto",IF(R15>=5,"Medio","Bajo"))))
A16: =IF(B16="","","SC-"&TEXT(ROW()-12,"000")) | R16: =IF(OR(P16="",Q16=""),"",P16*Q16) | S16: =IF(R16="","",IF(R16>=17,"Crítico",IF(R16>=10,"Alto",IF(R16>=5,"Medio","Bajo"))))
A17: =IF(B17="","","SC-"&TEXT(ROW()-12,"000")) | R17: =IF(OR(P17="",Q17=""),"",P17*Q17) | S17: =IF(R17="","",IF(R17>=17,"Crítico",IF(R17>=10,"Alto",IF(R17>=5,"Medio","Bajo"))))
A18: =IF(B18="","","SC-"&TEXT(ROW()-12,"000")) | R18: =IF(OR(P18="",Q18=""),"",P18*Q18) | S18: =IF(R18="","",IF(R18>=17,"Crítico",IF(R18>=10,"Alto",IF(R18>=5,"Medio","Bajo"))))
A19: =IF(B19="","","SC-"&TEXT(ROW()-12,"000")) | R19: =IF(OR(P19="",Q19=""),"",P19*Q19) | S19: =IF(R19="","",IF(R19>=17,"Crítico",IF(R19>=10,"Alto",IF(R19>=5,"Medio","Bajo"))))
A20: =IF(B20="","","SC-"&TEXT(ROW()-12,"000")) | R20: =IF(OR(P20="",Q20=""),"",P20*Q20) | S20: =IF(R20="","",IF(R20>=17,"Crítico",IF(R20>=10,"Alto",IF(R20>=5,"Medio","Bajo"))))
A21: =IF(B21="","","SC-"&TEXT(ROW()-12,"000")) | R21: =IF(OR(P21="",Q21=""),"",P21*Q21) | S21: =IF(R21="","",IF(R21>=17,"Crítico",IF(R21>=10,"Alto",IF(R21>=5,"Medio","Bajo"))))
A22: =IF(B22="","","SC-"&TEXT(ROW()-12,"000")) | R22: =IF(OR(P22="",Q22=""),"",P22*Q22) | S22: =IF(R22="","",IF(R22>=17,"Crítico",IF(R22>=10,"Alto",IF(R22>=5,"Medio","Bajo"))))
A23: =IF(B23="","","SC-"&TEXT(ROW()-12,"000")) | R23: =IF(OR(P23="",Q23=""),"",P23*Q23) | S23: =IF(R23="","",IF(R23>=17,"Crítico",IF(R23>=10,"Alto",IF(R23>=5,"Medio","Bajo"))))
A24: =IF(B24="","","SC-"&TEXT(ROW()-12,"000")) | R24: =IF(OR(P24="",Q24=""),"",P24*Q24) | S24: =IF(R24="","",IF(R24>=17,"Crítico",IF(R24>=10,"Alto",IF(R24>=5,"Medio","Bajo"))))
... A112: =IF(B112="","","SC-"&TEXT(ROW()-12,"000")) | R112: =IF(OR(P112="",Q112=""),"",P112*Q112) | S112: =IF(R112="","",IF(R112>=17,"Crítico",IF(R112>=10,"Alto",IF(R112>=5,"Medio","Bajo"))))

Sheet Solicitud de cambio
A1: #VALUE! | B1: BARRIO SOLIDARIO
B2: Solicitud, evaluación y aprobación de cambio
A5: 1. IDENTIFICACIÓN DE LA SOLICITUD
A6: Código del cambio | B6: Código del cambio | E6: Fecha de solicitud | F6: Fecha de solicitud | I6: Prioridad | J6: Prioridad
A7: Solicitante | B7: Solicitante | G7: Tipo de cambio | H7: Tipo de cambio
A8: Título | B8: Título
A9: Descripción | B9: Descripción
A10: Descripción | B10: Descripción
A11: Descripción | B11: Descripción
A12: Justificación / beneficio | B12: Justificación / beneficio
A13: Justificación / beneficio | B13: Justificación / beneficio
A14: Justificación / beneficio | B14: Justificación / beneficio
A16: 2. ALCANCE Y TRAZABILIDAD
A17: Elemento afectado | B17: Elemento afectado | G17: Versión actual | H17: Versión actual
A18: Requisito / HU / tarea Jira | B18: Requisito / HU / tarea Jira
A19: Archivos, módulos o documentos afectados | B19: Archivos, módulos o documentos afectados
A20: Archivos, módulos o documentos afectados | B20: Archivos, módulos o documentos afectados
A21: Archivos, módulos o documentos afectados | B21: Archivos, módulos o documentos afectados
A22: Criterios de aceptación del cambio | B22: Criterios de aceptación del cambio
A23: Criterios de aceptación del cambio | B23: Criterios de aceptación del cambio
A24: Criterios de aceptación del cambio | B24: Criterios de aceptación del cambio
A26: 3. ANÁLISIS DE IMPACTO Y RIESGO
A27: Analista | B27: Analista | G27: Esfuerzo estimado (h) | H27: Esfuerzo estimado (h)
A28: Impacto en alcance | B28: Impacto en alcance | E28: Cronograma | F28: Cronograma | I28: Costo | J28: Costo
A29: Calidad | B29: Calidad | E29: Seguridad / privacidad | F29: Seguridad / privacidad | I29: Compatibilidad | J29: Compatibilidad
A30: Probabilidad (1–5) | B30: Probabilidad (1–5) | E30: Impacto (1–5) | F30: Impacto (1–5) | I30: Exposición | J30: Exposición | K30: =IF(OR(C30="",G30=""),"",C30*G30)
A31: Riesgos y dependencias | B31: Riesgos y dependencias
A32: Riesgos y dependencias | B32: Riesgos y dependencias
A33: Riesgos y dependencias | B33: Riesgos y dependencias
A34: Plan de reversión / contingencia | B34: Plan de reversión / contingencia
A35: Plan de reversión / contingencia | B35: Plan de reversión / contingencia
A36: Plan de reversión / contingencia | B36: Plan de reversión / contingencia
A38: 4. DECISIÓN Y PLANIFICACIÓN
A39: Aprobador | B39: Aprobador | G39: Decisión | H39: Decisión
A40: Fecha de decisión | B40: Fecha de decisión | E40: Fecha objetivo | F40: Fecha objetivo | I40: Versión objetivo | J40: Versión objetivo
A41: Condiciones / motivo de rechazo | B41: Condiciones / motivo de rechazo
A42: Condiciones / motivo de rechazo | B42: Condiciones / motivo de rechazo
A43: Condiciones / motivo de rechazo | B43: Condiciones / motivo de rechazo
A44: Plan de implementación y responsable | B44: Plan de implementación y responsable
A45: Plan de implementación y responsable | B45: Plan de implementación y responsable
...

Sheet Catálogos
A1: Tipo | B1: Origen | C1: Prioridad | D1: Urgencia | E1: Complejidad | F1: Decisión | G1: Estado | H1: Validación | I1: Nivel de impacto | J1: Probabilidad / Impacto | K1: Responsables | L1: Roles del flujo
A2: Software | B2: Requisito | C2: Highest | D2: Alta | E2: Alta | F2: Aprobar | G2: Registrado | H2: Pendiente | I2: Sin impacto | J2: 1 | K2: Alex Mendoza Morante | L2: Solicitante
A3: Documentación | B3: Defecto | C3: High | D3: Media | E3: Media | F3: Aprobar con condiciones | G3: En análisis | H3: Conforme | I3: Bajo | J3: 2 | K3: Víctor Tello Bravo | L3: Analista de impacto
A4: Configuración | B4: Mejora | C4: Low | D4: Baja | E4: Baja | F4: Rechazar | G4: Pendiente de aprobación | H4: Con observaciones | I4: Medio | J4: 3 | K4: Kevin Carriel Bonoso | L4: Aprobador
A5: Base de datos | B5: Riesgo | C5: Lowest | F5: Devolver para ajuste | G5: Aprobado | H5: No conforme | I5: Alto | J5: 4 | K5: Mario Luzardo Fierro | L5: Implementador
A6: Interfaz / UX | B6: Revisión académica | G6: Rechazado | H6: No aplica | J6: 5 | K6: Luis Ramírez Conejo | L6: Validador
A7: Seguridad | B7: Cambio normativo | G7: Planificado | K7: Luis Rodríguez Barrera
A8: Infraestructura | B8: Decisión técnica | G8: En implementación | K8: Ing. Victoria García Velásquez
G9: En validación
G10: Cerrado
G11: Cancelado
