Workbook

Sheet Resumen
B1: BARRIO SOLIDARIO
B2: Resumen de gestión de cambios
B4: Indicador | D4: Resultado | F4: Etapa | G4: Responsable principal | H4: Resultado esperado | K4: Identificación del documento
B5: Total de solicitudes | D5: =COUNTIF('Registro de cambios'!C15:C114,"<>") -> 0 | F5: 1. Registro | G5: Solicitante | H5: Solicitud completa y trazable | K5: Documento | L5: Formato de Gestión de Cambios
B6: En análisis | D6: =COUNTIF('Registro de cambios'!Z15:Z114,"En análisis") -> 0 | F6: 2. Análisis | G6: Analista funcional/técnico | H6: Impactos, riesgo y esfuerzo estimados | K6: Proyecto | L6: Barrio Solidario
B7: Pendientes de aprobación | D7: =COUNTIF('Registro de cambios'!Z15:Z114,"Pendiente de aprobación") -> 0 | F7: 3. Decisión | G7: Product Owner / aprobador | H7: Decisión y condiciones documentadas | K7: Aplicación | L7: Software y documentación
B8: Aprobadas | D8: =COUNTIF('Registro de cambios'!Z15:Z114,"Aprobado") -> 0 | F8: 4. Planificación | G8: Scrum Master / equipo | H8: Fecha, responsable y versión objetivo | K8: Versión vigente | L8: 1.1.0
B9: En implementación | D9: =COUNTIF('Registro de cambios'!Z15:Z114,"En implementación") -> 0 | F9: 5. Implementación | G9: Responsable asignado | H9: Cambio aplicado y evidencia registrada | K9: Estado | L9: En elaboración
B10: En validación | D10: =COUNTIF('Registro de cambios'!Z15:Z114,"En validación") -> 0 | F10: 6. Validación | G10: Calidad / Product Owner | H10: Criterios y pruebas conformes | K10: Fecha de creación | L10: 14/09/2026
B11: Cerradas | D11: =COUNTIF('Registro de cambios'!Z15:Z114,"Cerrado") -> 0 | F11: 7. Cierre | G11: Aprobador | H11: Versión actualizada y lecciones registradas | K11: Propietario | L11: Víctor Tello Bravo / Product Owner
B12: Rechazadas | D12: =COUNTIF('Registro de cambios'!Z15:Z114,"Rechazado") -> 0 | K12: Consolidación | L12: Alex Mendoza Morante / Scrum Master
B13: Vencidas abiertas | D13: =COUNTIFS('Registro de cambios'!AA15:AA114,"<"&TODAY(),'Registro de cambios'!AA15:AA114,"<>",'Registro de cambios'!Z15:Z114,"<>Cerrado",'Registro de cambios'!Z15:Z114,"<>Cancelado",'Registro de cambios'!Z15:Z114,"<>Rechazado") -> 0 | K13: Revisión técnica | L13: Kevin Carriel Bonoso / Arquitecto de software
K14: Revisión de calidad | L14: Luis Rodríguez Barrera / Calidad y seguridad
B17: Control de versiones
B18: Versión | C18: Fecha | D18: Descripción | G18: Responsable | H18: Revisor | I18: Estado
B19: 0.1.0 | C19: 14/09/2026 | D19: Definición del flujo y campos | G19: Víctor Tello | H19: Alex Mendoza | I19: Completado
B20: 0.2.0 | C20: 14/09/2026 | D20: Controles de impacto, riesgo y validación | G20: Kevin Carriel / Luis Rodríguez | H20: Víctor Tello | I20: Completado
B21: 0.9.0 | C21: 14/09/2026 | D21: Revisión integral del formato | G21: Alex Mendoza | H21: Equipo del proyecto | I21: Revisado
B22: 1.0.0 | C22: 14/09/2026 | D22: Versión consolidada para Sprint 3 | G22: Alex Mendoza | H22: Ing. Victoria García Velásquez | I22: En elaboración
B24: 1.1.0 | C24: 15/09/2026 | D24: Incorporación de datos del solicitante, activos, recursos, pruebas QA, constancias y verificación posterior | G24: Alex Mendoza Morante | H24: Equipo del proyecto | I24: En revisión

Sheet Registro de cambios
B2: BARRIO SOLIDARIO
B3: Registro y seguimiento de solicitudes de cambio
B4: Versión: 1.0.0 | C4: Propietario: Víctor Tello / Product Owner | E4: Consolidación: Alex Mendoza / Scrum Master | G4: Estado: En elaboración
B5: Actualización: 14/09/2026 | C5: Revisión técnica: Kevin Carriel | E5: Aprobación académica: Ing. Victoria García Velásquez
B7: CONTROL GENERAL DE CAMBIOS
B9: Total | F9: Pendientes de aprobación | J9: Aprobados | N9: En implementación | R9: Cerrados | V9: Rechazados | Z9: Vencidos abiertos | AD9: Estado del control
B10: =COUNTIF(C15:C114,"<>") -> 0 | F10: =COUNTIF(Z15:Z114,"Pendiente de aprobación") -> 0 | J10: =COUNTIF(Z15:Z114,"Aprobado") -> 0 | N10: =COUNTIF(Z15:Z114,"En implementación") -> 0 | R10: =COUNTIF(Z15:Z114,"Cerrado") -> 0 | V10: =COUNTIF(Z15:Z114,"Rechazado") -> 0 | Z10: =COUNTIFS(AA15:AA114,"<"&TODAY(),AA15:AA114,"<>",Z15:Z114,"<>Cerrado",Z15:Z114,"<>Cancelado",Z15:Z114,"<>Rechazado") -> 0 | AD10: =IF(Z10>0,"REQUIERE ATENCIÓN",IF(F10>0,"PENDIENTE DE DECISIÓN","AL DÍA")) -> AL DÍA
B12: Flujo recomendado: registrar → analizar impacto y riesgo → decidir → planificar → implementar → validar → cerrar. Los cambios rechazados o cancelados conservan su trazabilidad.
B14: Código | C14: Fecha de solicitud | D14: Tipo de cambio | E14: Origen | F14: Título del cambio | G14: Descripción y justificación | H14: Elemento afectado | I14: Versión actual | J14: Prioridad | K14: Urgencia | L14: Impacto alcance | M14: Impacto cronograma | N14: Impacto costo | O14: Impacto calidad | P14: Impacto seguridad | Q14: Probabilidad | R14: Impacto del riesgo | S14: Exposición | T14: Nivel de riesgo | U14: Esfuerzo estimado (h) | V14: Solicitante | W14: Analista de impacto | X14: Aprobador | Y14: Decisión | Z14: Estado | AA14: Fecha objetivo | AB14: Fecha implementación | AC14: Resultado de validación | AD14: Validador | AE14: Evidencia / enlace | AF14: Versión resultante | AG14: Observaciones | AH14: Correo / contacto | AI14: Área solicitante | AJ14: Jefatura / responsable | AK14: Activos afectados | AL14: Recursos necesarios | AM14: Pruebas en QA | AN14: Detalle de pruebas QA | AO14: Proceso de pruebas planificado | AP14: Constancia de aprobación | AQ14: Constancia de implementación | AR14: Fecha real de finalización | AS14: Verificación posterior | AT14: Resultado posterior
S15: =IF(OR(Q15="",R15=""),"",Q15*R15) | T15: =IF(S15="","",IF(S15>=17,"Crítico",IF(S15>=10,"Alto",IF(S15>=5,"Medio","Bajo"))))
B16: =IF(C16="","","SC-"&TEXT(ROW()-12,"000")) | S16: =IF(OR(Q16="",R16=""),"",Q16*R16) | T16: =IF(S16="","",IF(S16>=17,"Crítico",IF(S16>=10,"Alto",IF(S16>=5,"Medio","Bajo"))))
B17: =IF(C17="","","SC-"&TEXT(ROW()-12,"000")) | S17: =IF(OR(Q17="",R17=""),"",Q17*R17) | T17: =IF(S17="","",IF(S17>=17,"Crítico",IF(S17>=10,"Alto",IF(S17>=5,"Medio","Bajo"))))
B18: =IF(C18="","","SC-"&TEXT(ROW()-12,"000")) | S18: =IF(OR(Q18="",R18=""),"",Q18*R18) | T18: =IF(S18="","",IF(S18>=17,"Crítico",IF(S18>=10,"Alto",IF(S18>=5,"Medio","Bajo"))))
B19: =IF(C19="","","SC-"&TEXT(ROW()-12,"000")) | S19: =IF(OR(Q19="",R19=""),"",Q19*R19) | T19: =IF(S19="","",IF(S19>=17,"Crítico",IF(S19>=10,"Alto",IF(S19>=5,"Medio","Bajo"))))
B20: =IF(C20="","","SC-"&TEXT(ROW()-12,"000")) | S20: =IF(OR(Q20="",R20=""),"",Q20*R20) | T20: =IF(S20="","",IF(S20>=17,"Crítico",IF(S20>=10,"Alto",IF(S20>=5,"Medio","Bajo"))))
B21: =IF(C21="","","SC-"&TEXT(ROW()-12,"000")) | S21: =IF(OR(Q21="",R21=""),"",Q21*R21) | T21: =IF(S21="","",IF(S21>=17,"Crítico",IF(S21>=10,"Alto",IF(S21>=5,"Medio","Bajo"))))
B22: =IF(C22="","","SC-"&TEXT(ROW()-12,"000")) | S22: =IF(OR(Q22="",R22=""),"",Q22*R22) | T22: =IF(S22="","",IF(S22>=17,"Crítico",IF(S22>=10,"Alto",IF(S22>=5,"Medio","Bajo"))))
B23: =IF(C23="","","SC-"&TEXT(ROW()-12,"000")) | S23: =IF(OR(Q23="",R23=""),"",Q23*R23) | T23: =IF(S23="","",IF(S23>=17,"Crítico",IF(S23>=10,"Alto",IF(S23>=5,"Medio","Bajo"))))
B24: =IF(C24="","","SC-"&TEXT(ROW()-12,"000")) | S24: =IF(OR(Q24="",R24=""),"",Q24*R24) | T24: =IF(S24="","",IF(S24>=17,"Crítico",IF(S24>=10,"Alto",IF(S24>=5,"Medio","Bajo"))))
B25: =IF(C25="","","SC-"&TEXT(ROW()-12,"000")) | S25: =IF(OR(Q25="",R25=""),"",Q25*R25) | T25: =IF(S25="","",IF(S25>=17,"Crítico",IF(S25>=10,"Alto",IF(S25>=5,"Medio","Bajo"))))
B26: =IF(C26="","","SC-"&TEXT(ROW()-12,"000")) | S26: =IF(OR(Q26="",R26=""),"",Q26*R26) | T26: =IF(S26="","",IF(S26>=17,"Crítico",IF(S26>=10,"Alto",IF(S26>=5,"Medio","Bajo"))))
B27: =IF(C27="","","SC-"&TEXT(ROW()-12,"000")) | S27: =IF(OR(Q27="",R27=""),"",Q27*R27) | T27: =IF(S27="","",IF(S27>=17,"Crítico",IF(S27>=10,"Alto",IF(S27>=5,"Medio","Bajo"))))
... B114: =IF(C114="","","SC-"&TEXT(ROW()-12,"000")) | S114: =IF(OR(Q114="",R114=""),"",Q114*R114) | T114: =IF(S114="","",IF(S114>=17,"Crítico",IF(S114>=10,"Alto",IF(S114>=5,"Medio","Bajo"))))

Sheet Solicitud de cambio
B2: BARRIO SOLIDARIO
B3: Solicitud, evaluación y aprobación de cambio
B5: 1. IDENTIFICACIÓN DE LA SOLICITUD
B6: Código del cambio | C6: Código del cambio | F6: Fecha de solicitud | G6: Fecha de solicitud | J6: Prioridad | K6: Prioridad
B7: Solicitante | C7: Solicitante | H7: Tipo de cambio | I7: Tipo de cambio
B8: Título | C8: Título
B9: Descripción | C9: Descripción
B10: Descripción | C10: Descripción
B11: Descripción | C11: Descripción
B12: Justificación / beneficio | C12: Justificación / beneficio
B13: Justificación / beneficio | C13: Justificación / beneficio
B14: Justificación / beneficio | C14: Justificación / beneficio
B16: 2. ALCANCE Y TRAZABILIDAD
B17: Elemento afectado | C17: Elemento afectado | H17: Versión actual | I17: Versión actual
B18: Requisito / HU / tarea Jira | C18: Requisito / HU / tarea Jira
B19: Archivos, módulos o documentos afectados | C19: Archivos, módulos o documentos afectados
B20: Archivos, módulos o documentos afectados | C20: Archivos, módulos o documentos afectados
B21: Archivos, módulos o documentos afectados | C21: Archivos, módulos o documentos afectados
B22: Criterios de aceptación del cambio | C22: Criterios de aceptación del cambio
B23: Criterios de aceptación del cambio | C23: Criterios de aceptación del cambio
B24: Criterios de aceptación del cambio | C24: Criterios de aceptación del cambio
B26: 3. ANÁLISIS DE IMPACTO Y RIESGO
B27: Analista | C27: Analista | H27: Esfuerzo estimado (h) | I27: Esfuerzo estimado (h)
B28: Impacto en alcance | C28: Impacto en alcance | F28: Cronograma | G28: Cronograma | J28: Costo | K28: Costo
B29: Calidad | C29: Calidad | F29: Seguridad / privacidad | G29: Seguridad / privacidad | J29: Compatibilidad | K29: Compatibilidad
B30: Probabilidad (1–5) | C30: Probabilidad (1–5) | F30: Impacto (1–5) | G30: Impacto (1–5) | J30: Exposición | K30: Exposición | L30: =IF(OR(D30="",H30=""),"",D30*H30)
B31: Riesgos y dependencias | C31: Riesgos y dependencias
B32: Riesgos y dependencias | C32: Riesgos y dependencias
B33: Riesgos y dependencias | C33: Riesgos y dependencias
B34: Plan de reversión / contingencia | C34: Plan de reversión / contingencia
B35: Plan de reversión / contingencia | C35: Plan de reversión / contingencia
B36: Plan de reversión / contingencia | C36: Plan de reversión / contingencia
B38: 4. DECISIÓN Y PLANIFICACIÓN
B39: Aprobador | C39: Aprobador | H39: Decisión | I39: Decisión
B40: Fecha de decisión | C40: Fecha de decisión | F40: Fecha objetivo | G40: Fecha objetivo | J40: Versión objetivo | K40: Versión objetivo
B41: Condiciones / motivo de rechazo | C41: Condiciones / motivo de rechazo
B42: Condiciones / motivo de rechazo | C42: Condiciones / motivo de rechazo
B43: Condiciones / motivo de rechazo | C43: Condiciones / motivo de rechazo
B44: Plan de implementación y responsable | C44: Plan de implementación y responsable
B45: Plan de implementación y responsable | C45: Plan de implementación y responsable
...

Sheet Catálogos
A1: Tipo | B1: Origen | C1: Prioridad | D1: Urgencia | E1: Complejidad | F1: Decisión | G1: Estado | H1: Validación | I1: Nivel de impacto | J1: Probabilidad / Impacto | K1: Responsables | L1: Roles del flujo | M1: Pruebas QA | N1: Verificación posterior | O1: Resultado posterior
A2: Software | B2: Requisito | C2: Highest | D2: Alta | E2: Alta | F2: Aprobar | G2: Registrado | H2: Pendiente | I2: Sin impacto | J2: 1 | K2: Alex Mendoza Morante | L2: Solicitante | M2: Sí | N2: Sí | O2: Conforme
A3: Documentación | B3: Defecto | C3: High | D3: Media | E3: Media | F3: Aprobar con condiciones | G3: En análisis | H3: Conforme | I3: Bajo | J3: 2 | K3: Víctor Tello Bravo | L3: Analista de impacto | M3: No | N3: No | O3: Con observaciones
A4: Configuración | B4: Mejora | C4: Low | D4: Baja | E4: Baja | F4: Rechazar | G4: Pendiente de aprobación | H4: Con observaciones | I4: Medio | J4: 3 | K4: Kevin Carriel Bonoso | L4: Aprobador | M4: No aplica | N4: No aplica | O4: No conforme
A5: Base de datos | B5: Riesgo | C5: Lowest | F5: Devolver para ajuste | G5: Aprobado | H5: No conforme | I5: Alto | J5: 4 | K5: Mario Luzardo Fierro | L5: Implementador | O5: No aplica
A6: Interfaz / UX | B6: Revisión académica | G6: Rechazado | H6: No aplica | J6: 5 | K6: Luis Ramírez Conejo | L6: Validador
A7: Seguridad | B7: Cambio normativo | G7: Planificado | K7: Luis Rodríguez Barrera
A8: Infraestructura | B8: Decisión técnica | G8: En implementación | K8: Ing. Victoria García Velásquez
G9: En validación
G10: Cerrado
G11: Cancelado
