Workbook

Sheet Resumen
B2: BARRIO SOLIDARIO · Matriz integrada de evidencias
B3: Consolida la evidencia de calidad y riesgos del MVP y permite rastrear cada criterio o riesgo hasta un paquete verificable.
B5: Indicador | C5: Resultado | D5: Interpretación | F5: Estado | G5: Cantidad | H5: Responsable de consolidación | I5: Fecha de corte | J5: Estado general
B6: Paquetes de evidencia | C6: =COUNTA('Matriz de evidencias'!A10:A52) -> 43 | D6: Evidencias agrupadas sin duplicación | F6: Verificada | G6: =COUNTIF('Matriz de evidencias'!N10:N52,F6) -> 21 | H6: Alex Mendoza Morante | I6: 46296 | J6: EN SEGUIMIENTO
B7: Verificadas | C7: =COUNTIF('Matriz de evidencias'!N10:N52,"Verificada") -> 21 | D7: Declaradas verificadas por el equipo; requieren referencia específica y resultado adjunto para auditoría independiente. | F7: En proceso | G7: =COUNTIF('Matriz de evidencias'!N10:N52,F7) -> 12 | H7: Luis Rodríguez Barrera | I7: 46296
B8: En proceso | C8: =COUNTIF('Matriz de evidencias'!N10:N52,"En proceso") -> 12 | D8: Requieren completar o revalidar | F8: Pendiente | G8: =COUNTIF('Matriz de evidencias'!N10:N52,F8) -> 10
B9: Pendientes | C9: =COUNTIF('Matriz de evidencias'!N10:N52,"Pendiente") -> 10 | D9: Aún no iniciadas
B10: Resultados conformes | C10: =COUNTIF('Matriz de evidencias'!O10:O52,"Conforme") -> 21 | D10: Resultado satisfactorio
B11: Resultados parciales | C11: =COUNTIF('Matriz de evidencias'!O10:O52,"Parcial") -> 12 | D11: Existe evidencia, pero requiere cierre
B12: Criterios de calidad vinculados | C12: =COUNTIF(Trazabilidad!B7:B134,"Matriz de calidad") -> 64 | D12: Cobertura de la matriz DOC-08
B13: Riesgos vinculados | C13: =COUNTIF(Trazabilidad!B7:B134,"Matriz de riesgos") -> 54 | D13: Cobertura de la matriz DOC-09
B14: Flujos Django añadidos | C14: 10 | D14: Pruebas funcionales nuevas pendientes de adjuntar
B16: Criterios de uso
B17: 1. | C17: Una evidencia puede respaldar varios criterios de calidad y riesgos cuando el método, resultado y responsable son coincidentes.
B18: 2. | C18: La hoja Trazabilidad conserva una relación individual para los 64 criterios de calidad, 54 riesgos y 10 flujos Django añadidos.
B19: 3. | C19: Los estados En proceso requieren completar el archivo, enlace o revalidación antes del cierre del Sprint 4, el 04/10/2026.
B20: 4. | C20: No deben adjuntarse datos personales reales, contraseñas, tokens, archivos .env ni capturas que revelen información sensible.
B21: 5. | C21: Los enlaces generales de Jira y GitHub se incluyen como referencia; cada evidencia debe adjuntarse también a su tarea o carpeta específica.
B22: Estado de validación | C22: La matriz está planificada; los paquetes pendientes y en proceso no acreditan pruebas ejecutadas.
B23: Jira | C23: https://uees-team-kgpqd887.atlassian.net/jira/software/projects/SCRUM/summary
B24: GitHub | C24: https://github.com/UESSalexmendoza/Proyecto-Ingenieria-II/tree/main

Sheet Matriz de evidencias
A2: Registro y seguimiento de evidencias del MVP
A3: Corte al 01/10/2026 · Cada registro agrupa evidencia reutilizable y su cobertura se calcula desde la hoja Trazabilidad.
A5: Total | B5: Verificadas | C5: En proceso | D5: Pendientes | E5: Conformes | F5: Parciales | G5: Calidad vinculada | H5: Riesgos vinculados
A6: =COUNTA(A10:A52) -> 43 | B6: =COUNTIF(N10:N52,"Verificada") -> 21 | C6: =COUNTIF(N10:N52,"En proceso") -> 12 | D6: =COUNTIF(N10:N52,"Pendiente") -> 10 | E6: =COUNTIF(O10:O52,"Conforme") -> 21 | F6: =COUNTIF(O10:O52,"Parcial") -> 12 | G6: =SUM(E10:E52) -> 64 | H6: =SUM(F10:F52) -> 54
A9: Código | B9: Categoría | C9: Evidencia / paquete | D9: Descripción y contenido mínimo | E9: Criterios calidad | F9: Riesgos | G9: Tipo | H9: Responsable | I9: Verificador | J9: Prioridad | K9: Fecha prevista | L9: Fecha revisión | M9: Ubicación / referencia | N9: Estado | O9: Resultado | P9: Versión / documento | Q9: Referencia Jira | R9: Referencia GitHub | S9: Observación / acción siguiente
A10: EV-001 | B10: Alcance | C10: Alcance aprobado y control del MVP | D10: Documento del MVP, backlog priorizado, exclusiones y solicitudes de cambio que demuestran que el incremento permanece dentro del alcance aprobado. | E10: =COUNTIFS(Trazabilidad!$F$7:$F$134,$A10,Trazabilidad!$B$7:$B$134,"Matriz de calidad") -> 1 | F10: =COUNTIFS(Trazabilidad!$F$7:$F$134,$A10,Trazabilidad!$B$7:$B$134,"Matriz de riesgos") -> 2 | G10: Documento y registro | H10: Víctor Tello Bravo | I10: Alex Mendoza Morante | J10: Highest | K10: 46291 | L10: 46291 | M10: Documento de Visión / Jira | N10: Verificada | O10: Conforme | P10: 1.0 | Q10: Proyecto SCRUM | R10: Repositorio principal | S10: El alcance del MVP se encuentra delimitado y sujeto al proceso de control de cambios.
A11: EV-002 | B11: Funcionalidad | C11: Portal público y navegación | D11: Capturas y pruebas de los contenidos públicos, enlaces principales, encabezado, pie de página y acceso a las páginas informativas. | E11: =COUNTIFS(Trazabilidad!$F$7:$F$134,$A11,Trazabilidad!$B$7:$B$134,"Matriz de calidad") -> 2 | F11: =COUNTIFS(Trazabilidad!$F$7:$F$134,$A11,Trazabilidad!$B$7:$B$134,"Matriz de riesgos") -> 0 | G11: Capturas y prueba funcional | H11: Mario Luzardo Fierro | I11: Víctor Tello Bravo | J11: High | K11: 46291 | L11: 46291 | M11: Jira / Evidencias/EV-002 | N11: Verificada | O11: Conforme | P11: 1.0 | Q11: Proyecto SCRUM | R11: Repositorio principal | S11: El recorrido público fue comprobado sin enlaces bloqueantes.
A12: EV-003 | B12: Funcionalidad | C12: Registro y validación de usuarios | D12: Casos válidos, inválidos y duplicados, mensajes mostrados y consulta anonimizada de la cuenta creada en MySQL. | E12: =COUNTIFS(Trazabilidad!$F$7:$F$134,$A12,Trazabilidad!$B$7:$B$134,"Matriz de calidad") -> 3 | F12: =COUNTIFS(Trazabilidad!$F$7:$F$134,$A12,Trazabilidad!$B$7:$B$134,"Matriz de riesgos") -> 1 | G12: Prueba y captura | H12: Luis Ramírez Conejo | I12: Luis Rodríguez Barrera | J12: Highest | K12: 46291 | L12: 46291 | M12: Jira / Evidencias/EV-003 | N12: Verificada | O12: Conforme | P12: 1.0 | Q12: Proyecto SCRUM | R12: Repositorio principal | S12: El registro persiste datos válidos y rechaza entradas incorrectas o duplicadas.
A13: EV-004 | B13: Seguridad | C13: Inicio, cierre de sesión y rutas privadas | D13: Pruebas con credenciales válidas e inválidas, cierre de sesión y acceso directo a rutas privadas antes y después de autenticarse. | E13: =COUNTIFS(Trazabilidad!$F$7:$F$134,$A13,Trazabilidad!$B$7:$B$134,"Matriz de calidad") -> 4 | F13: =COUNTIFS(Trazabilidad!$F$7:$F$134,$A13,Trazabilidad!$B$7:$B$134,"Matriz de riesgos") -> 3 | G13: Prueba funcional y seguridad | H13: Kevin Carriel Bonoso | I13: Luis Rodríguez Barrera | J13: Highest | K13: 46291 | L13: 46292 | M13: Jira / Evidencias/EV-004 | N13: Verificada | O13: Conforme | P13: 1.0 | Q13: Proyecto SCRUM | R13: Repositorio principal | S13: Las sesiones y rutas privadas responden según el estado de autenticación.
A14: EV-005 | B14: Funcionalidad | C14: Recuperación y cambio de contraseña | D14: Correo, enlace, token, caducidad, pantalla de cambio y comprobación de que la clave anterior deja de funcionar. | E14: =COUNTIFS(Trazabilidad!$F$7:$F$134,$A14,Trazabilidad!$B$7:$B$134,"Matriz de calidad") -> 2 | F14: =COUNTIFS(Trazabilidad!$F$7:$F$134,$A14,Trazabilidad!$B$7:$B$134,"Matriz de riesgos") -> 1 | G14: Prueba integral | H14: Luis Ramírez Conejo | I14: Luis Rodríguez Barrera | J14: High | K14: 46292 | M14: Jira / Evidencias/EV-005 | N14: En proceso | O14: Parcial | P14: 1.0 | Q14: Proyecto SCRUM | R14: Repositorio principal | S14: Completar la validación integral de token, caducidad y notificación antes del 03/10/2026.
A15: EV-006 | B15: Seguridad | C15: Roles, permisos y panel autorizado | D15: Matriz de permisos y pruebas por rol sobre opciones visibles, rutas protegidas y peticiones directas al servidor. | E15: =COUNTIFS(Trazabilidad!$F$7:$F$134,$A15,Trazabilidad!$B$7:$B$134,"Matriz de calidad") -> 2 | F15: =COUNTIFS(Trazabilidad!$F$7:$F$134,$A15,Trazabilidad!$B$7:$B$134,"Matriz de riesgos") -> 2 | G15: Matriz y pruebas negativas | H15: Kevin Carriel Bonoso | I15: Luis Rodríguez Barrera | J15: Highest | K15: 46292 | M15: Jira / Evidencias/EV-006 | N15: En proceso | O15: Parcial | P15: 1.0 | Q15: Proyecto SCRUM | R15: Repositorio principal | S15: Completar todos los roles del MVP y las pruebas de autorización antes del 02/10/2026.
A16: EV-007 | B16: Datos | C16: Perfil y persistencia de datos | D16: Prueba antes y después de actualizar datos permitidos, validación del usuario autenticado y consulta de persistencia. | E16: =COUNTIFS(Trazabilidad!$F$7:$F$134,$A16,Trazabilidad!$B$7:$B$134,"Matriz de calidad") -> 2 | F16: =COUNTIFS(Trazabilidad!$F$7:$F$134,$A16,Trazabilidad!$B$7:$B$134,"Matriz de riesgos") -> 1 | G16: Prueba y consulta de datos | H16: Luis Ramírez Conejo | I16: Luis Rodríguez Barrera | J16: High | K16: 46292 | L16: 46292 | M16: Jira / Evidencias/EV-007 | N16: Verificada | O16: Conforme | P16: 1.0 | Q16: Proyecto SCRUM | R16: Repositorio principal | S16: Los datos permitidos se actualizan y permanecen asociados al usuario correcto.
A17: EV-008 | B17: Seguridad | C17: Hash y política de contraseñas | D17: Consulta anonimizada del hash y pruebas de reglas de complejidad, longitud y rechazo de contraseñas no conformes. | E17: =COUNTIFS(Trazabilidad!$F$7:$F$134,$A17,Trazabilidad!$B$7:$B$134,"Matriz de calidad") -> 2 | F17: =COUNTIFS(Trazabilidad!$F$7:$F$134,$A17,Trazabilidad!$B$7:$B$134,"Matriz de riesgos") -> 1 | G17: Revisión técnica y prueba | H17: Luis Rodríguez Barrera | I17: Kevin Carriel Bonoso | J17: Highest | K17: 46292 | L17: 46292 | M17: GitHub / Evidencias/EV-008 | N17: Verificada | O17: Conforme | P17: 1.0 | Q17: Proyecto SCRUM | R17: Repositorio principal | S17: No se identificaron contraseñas legibles en datos, código ni evidencias.
A18: EV-009 | B18: Seguridad | C18: Validación del servidor y manejo de errores | D18: Pruebas directas con entradas inválidas o manipuladas y capturas de mensajes controlados sin trazas ni datos internos. | E18: =COUNTIFS(Trazabilidad!$F$7:$F$134,$A18,Trazabilidad!$B$7:$B$134,"Matriz de calidad") -> 3 | F18: =COUNTIFS(Trazabilidad!$F$7:$F$134,$A18,Trazabilidad!$B$7:$B$134,"Matriz de riesgos") -> 2 | G18: Pruebas negativas | H18: Luis Rodríguez Barrera | I18: Kevin Carriel Bonoso | J18: Highest | K18: 46292 | L18: 46292 | M18: Jira / Evidencias/EV-009 | N18: Verificada | O18: Conforme | P18: 1.0 | Q18: Proyecto SCRUM | R18: Repositorio principal | S18: Las entradas se validan en el servidor y los errores no exponen información sensible.
A19: EV-010 | B19: Seguridad | C19: Configuración, secretos y repositorio | D19: Revisión de variables de entorno, settings, archivos ignorados e historial para confirmar que no existen credenciales publicadas. | E19: =COUNTIFS(Trazabilidad!$F$7:$F$134,$A19,Trazabilidad!$B$7:$B$134,"Matriz de calidad") -> 2 | F19: =COUNTIFS(Trazabilidad!$F$7:$F$134,$A19,Trazabilidad!$B$7:$B$134,"Matriz de riesgos") -> 2 | G19: Revisión de código | H19: Kevin Carriel Bonoso | I19: Luis Rodríguez Barrera | J19: Highest | K19: 46292 | L19: 46292 | M19: GitHub / Evidencias/EV-010 | N19: Verificada | O19: Conforme | P19: 1.0 | Q19: Proyecto SCRUM | R19: Repositorio principal | S19: La configuración sensible se mantiene fuera del código versionado.
A20: EV-011 | B20: Privacidad | C20: Minimización y anonimización de datos | D20: Revisión de formularios, modelo y capturas para comprobar que solo se recopilan datos necesarios y se utilizan datos ficticios. | E20: =COUNTIFS(Trazabilidad!$F$7:$F$134,$A20,Trazabilidad!$B$7:$B$134,"Matriz de calidad") -> 1 | F20: =COUNTIFS(Trazabilidad!$F$7:$F$134,$A20,Trazabilidad!$B$7:$B$134,"Matriz de riesgos") -> 2 | G20: Inspección documental | H20: Luis Rodríguez Barrera | I20: Víctor Tello Bravo | J20: High | K20: 46292 | L20: 46292 | M20: Documentos / Evidencias/EV-011 | N20: Verificada | O20: Conforme | P20: 1.0 | Q20: Proyecto SCRUM | R20: Repositorio principal | S20: Las evidencias no presentan correos, teléfonos ni claves reales.
A21: EV-012 | B21: Accesibilidad | C21: Contraste y comunicación no dependiente del color | D21: Mediciones de contraste y capturas de estados, mensajes e iconos que complementan el uso del color. | E21: =COUNTIFS(Trazabilidad!$F$7:$F$134,$A21,Trazabilidad!$B$7:$B$134,"Matriz de calidad") -> 2 | F21: =COUNTIFS(Trazabilidad!$F$7:$F$134,$A21,Trazabilidad!$B$7:$B$134,"Matriz de riesgos") -> 2 | G21: Lista de comprobación | H21: Mario Luzardo Fierro | I21: Luis Rodríguez Barrera | J21: Highest | K21: 46293 | L21: 46293 | M21: Jira / Evidencias/EV-012 | N21: Verificada | O21: Conforme | P21: 1.0 | Q21: Proyecto SCRUM | R21: Repositorio principal | S21: Los componentes principales cumplen los umbrales definidos.
A22: EV-013 | B22: Accesibilidad | C22: Teclado, foco y semántica de formularios | D22: Recorrido con Tab, Enter y espacio; capturas de foco; etiquetas asociadas y orden lógico de lectura. | E22: =COUNTIFS(Trazabilidad!$F$7:$F$134,$A22,Trazabilidad!$B$7:$B$134,"Matriz de calidad") -> 5 | F22: =COUNTIFS(Trazabilidad!$F$7:$F$134,$A22,Trazabilidad!$B$7:$B$134,"Matriz de riesgos") -> 3 | G22: Prueba manual y HTML | H22: Mario Luzardo Fierro | I22: Luis Rodríguez Barrera | J22: Highest | K22: 46293 | M22: Jira / Evidencias/EV-013 | N22: En proceso | O22: Parcial | P22: 1.0 | Q22: Proyecto SCRUM | R22: Repositorio principal | S22: Finalizar ajustes menores del orden de foco y repetir el recorrido antes del 02/10/2026.
A23: EV-014 | B23: Compatibilidad | C23: Zoom, diseño adaptable y navegadores | D23: Capturas al 200 %, resoluciones representativas y resultados de los flujos principales en Chrome y Edge. | E23: =COUNTIFS(Trazabilidad!$F$7:$F$134,$A23,Trazabilidad!$B$7:$B$134,"Matriz de calidad") -> 4 | F23: =COUNTIFS(Trazabilidad!$F$7:$F$134,$A23,Trazabilidad!$B$7:$B$134,"Matriz de riesgos") -> 2 | G23: Prueba de compatibilidad | H23: Mario Luzardo Fierro | I23: Luis Rodríguez Barrera | J23: High | K23: 46293 | L23: 46293 | M23: Jira / Evidencias/EV-014 | N23: Verificada | O23: Conforme | P23: 1.0 | Q23: Proyecto SCRUM | R23: Repositorio principal | S23: No se observó desplazamiento horizontal injustificado ni diferencias bloqueantes.
A24: EV-015 | B24: Usabilidad | C24: Lenguaje y recorrido para adultos mayores | D24: Revisión de textos, mensajes, cantidad de pasos y validación funcional del recorrido con apoyo de cuidador. | E24: =COUNTIFS(Trazabilidad!$F$7:$F$134,$A24,Trazabilidad!$B$7:$B$134,"Matriz de calidad") -> 2 | F24: =COUNTIFS(Trazabilidad!$F$7:$F$134,$A24,Trazabilidad!$B$7:$B$134,"Matriz de riesgos") -> 2 | G24: Revisión funcional | H24: Víctor Tello Bravo | I24: Luis Rodríguez Barrera | J24: High | K24: 46293 | M24: Jira / Evidencias/EV-015 | N24: En proceso | O24: Parcial | P24: 1.0 | Q24: Proyecto SCRUM | R24: Repositorio principal | S24: Ejecutar la validación final del recorrido asistido antes del 03/10/2026.
A25: EV-016 | B25: Identidad visual | C25: Paleta, jerarquía y componentes comunes | D25: Comparación con la paleta aprobada y capturas de encabezados, botones, tipografía y componentes reutilizados. | E25: =COUNTIFS(Trazabilidad!$F$7:$F$134,$A25,Trazabilidad!$B$7:$B$134,"Matriz de calidad") -> 10 | F25: =COUNTIFS(Trazabilidad!$F$7:$F$134,$A25,Trazabilidad!$B$7:$B$134,"Matriz de riesgos") -> 3 | G25: Inspección visual | H25: Mario Luzardo Fierro | I25: Víctor Tello Bravo | J25: High | K25: 46293 | L25: 46293 | M25: Jira / Evidencias/EV-016 | N25: Verificada | O25: Conforme | P25: 1.0 | Q25: Proyecto SCRUM | R25: Repositorio principal | S25: La identidad visual se presenta de forma uniforme en las pantallas principales.
A26: EV-017 | B26: Datos | C26: Base de datos, unicidad y respaldo | D26: Consultas anonimizadas, restricción única, persistencia tras reinicio y respaldo de los datos de demostración. | E26: =COUNTIFS(Trazabilidad!$F$7:$F$134,$A26,Trazabilidad!$B$7:$B$134,"Matriz de calidad") -> 0 | F26: =COUNTIFS(Trazabilidad!$F$7:$F$134,$A26,Trazabilidad!$B$7:$B$134,"Matriz de riesgos") -> 3 | G26: Consulta y respaldo | H26: Luis Ramírez Conejo | I26: Kevin Carriel Bonoso | J26: Highest | K26: 46294 | L26: 46294 | M26: GitHub / Evidencias/EV-017 | N26: Verificada | O26: Conforme | P26: 1.0 | Q26: Proyecto SCRUM | R26: Repositorio principal | S26: Los registros permanecen disponibles y la duplicidad de correo está controlada.
A27: EV-018 | B27: Rendimiento | C27: Tiempos de respuesta del MVP | D27: Registro de carga de páginas y respuesta de registro, inicio de sesión y perfil en ambiente local. | E27: =COUNTIFS(Trazabilidad!$F$7:$F$134,$A27,Trazabilidad!$B$7:$B$134,"Matriz de calidad") -> 2 | F27: =COUNTIFS(Trazabilidad!$F$7:$F$134,$A27,Trazabilidad!$B$7:$B$134,"Matriz de riesgos") -> 2 | G27: Medición técnica | H27: Kevin Carriel Bonoso | I27: Luis Rodríguez Barrera | J27: High | K27: 46294 | L27: 46294 | M27: Jira / Evidencias/EV-018 | N27: Verificada | O27: Conforme | P27: 1.0 | Q27: Proyecto SCRUM | R27: Repositorio principal | S27: Las operaciones críticas cumplen los umbrales definidos para pruebas locales.
A28: EV-019 | B28: Arquitectura | C28: Estructura, modelo y mantenibilidad | D28: Árbol del proyecto, separación de configuración, modelos, rutas y servicios, y comparación con el modelo documentado. | E28: =COUNTIFS(Trazabilidad!$F$7:$F$134,$A28,Trazabilidad!$B$7:$B$134,"Matriz de calidad") -> 5 | F28: =COUNTIFS(Trazabilidad!$F$7:$F$134,$A28,Trazabilidad!$B$7:$B$134,"Matriz de riesgos") -> 1 | G28: Revisión técnica | H28: Kevin Carriel Bonoso | I28: Luis Ramírez Conejo | J28: High | K28: 46294 | L28: 46294 | M28: GitHub / Evidencias/EV-019 | N28: Verificada | O28: Conforme | P28: 1.0 | Q28: Proyecto SCRUM | R28: Repositorio principal | S28: La estructura permite ubicar y mantener los componentes principales del MVP.
A29: EV-020 | B29: Integración | C29: Integración frontend y backend | D29: Ejecución del flujo principal conectado a rutas, formularios, servicios, sesión y base de datos. | E29: =COUNTIFS(Trazabilidad!$F$7:$F$134,$A29,Trazabilidad!$B$7:$B$134,"Matriz de calidad") -> 0 | F29: =COUNTIFS(Trazabilidad!$F$7:$F$134,$A29,Trazabilidad!$B$7:$B$134,"Matriz de riesgos") -> 1 | G29: Prueba de integración | H29: Kevin Carriel Bonoso | I29: Luis Rodríguez Barrera | J29: Highest | K29: 46294 | M29: Jira / Evidencias/EV-020 | N29: En proceso | O29: Parcial | P29: 1.0 | Q29: Proyecto SCRUM | R29: Repositorio principal | S29: Continuar pruebas integrales y corrección de incidencias hasta el 02/10/2026.
A30: EV-021 | B30: Aceptación | C30: Criterios de aceptación y recorrido funcional | D30: Lista de criterios, validación del Product Owner y guion que conecta problema, alcance, funciones y resultados. | E30: =COUNTIFS(Trazabilidad!$F$7:$F$134,$A30,Trazabilidad!$B$7:$B$134,"Matriz de calidad") -> 0 | F30: =COUNTIFS(Trazabilidad!$F$7:$F$134,$A30,Trazabilidad!$B$7:$B$134,"Matriz de riesgos") -> 3 | G30: Lista y validación | H30: Víctor Tello Bravo | I30: Alex Mendoza Morante | J30: Highest | K30: 46294 | L30: 46295 | M30: Documentos / Evidencias/EV-021 | N30: Verificada | O30: Conforme | P30: 1.0 | Q30: Proyecto SCRUM | R30: Repositorio principal | S30: Los criterios del MVP se encuentran definidos y asociados al recorrido de demostración.
A31: EV-022 | B31: Calidad | C31: Casos de prueba y regresión | D31: Casos positivos, negativos, smoke test y regresión de registro, acceso, sesión, panel, perfil y recuperación. | E31: =COUNTIFS(Trazabilidad!$F$7:$F$134,$A31,Trazabilidad!$B$7:$B$134,"Matriz de calidad") -> 0 | F31: =COUNTIFS(Trazabilidad!$F$7:$F$134,$A31,Trazabilidad!$B$7:$B$134,"Matriz de riesgos") -> 1 | G31: Casos y resultados | H31: Luis Rodríguez Barrera | I31: Víctor Tello Bravo | J31: Highest | K31: 46295 | M31: Jira / Evidencias/EV-022 | N31: En proceso | O31: Parcial | P31: 1.0 | Q31: Proyecto SCRUM | R31: Repositorio principal | S31: Completar escenarios negativos y adjuntar resultados faltantes antes del 03/10/2026.
A32: EV-023 | B32: Calidad | C32: Defectos y acciones correctivas | D32: Incidencias con descripción, prioridad, responsable, evidencia, fecha compromiso, corrección y resultado de revalidación. | E32: =COUNTIFS(Trazabilidad!$F$7:$F$134,$A32,Trazabilidad!$B$7:$B$134,"Matriz de calidad") -> 1 | F32: =COUNTIFS(Trazabilidad!$F$7:$F$134,$A32,Trazabilidad!$B$7:$B$134,"Matriz de riesgos") -> 2 | G32: Registro de defectos | H32: Luis Rodríguez Barrera | I32: Alex Mendoza Morante | J32: High | K32: 46295 | L32: 46296 | M32: Jira / Evidencias/EV-023 | N32: Verificada | O32: Conforme | P32: 1.0 | Q32: Proyecto SCRUM | R32: Repositorio principal | S32: Los defectos identificados cuentan con responsable y seguimiento.
A33: EV-024 | B33: Gestión | C33: Cronograma, asignaciones y seguimiento en Jira | D33: Cronograma de los sprints, tareas individuales, prioridades, fechas, estados y conciliación con archivos y commits. | E33: =COUNTIFS(Trazabilidad!$F$7:$F$134,$A33,Trazabilidad!$B$7:$B$134,"Matriz de calidad") -> 1 | F33: =COUNTIFS(Trazabilidad!$F$7:$F$134,$A33,Trazabilidad!$B$7:$B$134,"Matriz de riesgos") -> 4 | G33: Reporte Jira | H33: Alex Mendoza Morante | I33: Víctor Tello Bravo | J33: Highest | K33: 46295 | M33: Jira / Evidencias/EV-024 | N33: En proceso | O33: Parcial | P33: 1.0 | Q33: Proyecto SCRUM | R33: Repositorio principal | S33: Actualizar estados y adjuntos restantes antes del cierre del Sprint 4.
A34: EV-025 | B34: Calidad | C34: Matriz de gestión de calidad | D34: Matriz completa con resultados, valores, fechas, evidencias, observaciones y acciones correctivas. | E34: =COUNTIFS(Trazabilidad!$F$7:$F$134,$A34,Trazabilidad!$B$7:$B$134,"Matriz de calidad") -> 0 | F34: =COUNTIFS(Trazabilidad!$F$7:$F$134,$A34,Trazabilidad!$B$7:$B$134,"Matriz de riesgos") -> 0 | G34: Matriz de control | H34: Luis Rodríguez Barrera | I34: Alex Mendoza Morante | J34: Highest | K34: 46295 | L34: 46296 | M34: Documento DOC-08 | N34: Verificada | O34: Conforme | P34: 1.0 | Q34: Proyecto SCRUM | R34: Repositorio principal | S34: La evaluación registra 64 criterios y un estado general aprobado.
A35: EV-026 | B35: Riesgos | C35: Matriz de gestión de riesgos | D35: Matriz completa con exposición inicial y residual, tratamiento, evidencia, fecha de revisión y observaciones. | E35: =COUNTIFS(Trazabilidad!$F$7:$F$134,$A35,Trazabilidad!$B$7:$B$134,"Matriz de calidad") -> 0 | F35: =COUNTIFS(Trazabilidad!$F$7:$F$134,$A35,Trazabilidad!$B$7:$B$134,"Matriz de riesgos") -> 0 | G35: Matriz de control | H35: Kevin Carriel Bonoso | I35: Alex Mendoza Morante | J35: Highest | K35: 46295 | L35: 46296 | M35: Documento DOC-09 | N35: Verificada | O35: Conforme | P35: 1.0 | Q35: Proyecto SCRUM | R35: Repositorio principal | S35: Los 54 riesgos tienen evaluación residual y estado de seguimiento.
A36: EV-027 | B36: Documentación | C36: Documento de Visión y control de versiones | D36: Versión consolidada con alcance del MVP, calidad, riesgos, cambios, BPMN, Jira, arquitectura y registro de versiones. | E36: =COUNTIFS(Trazabilidad!$F$7:$F$134,$A36,Trazabilidad!$B$7:$B$134,"Matriz de calidad") -> 2 | F36: =COUNTIFS(Trazabilidad!$F$7:$F$134,$A36,Trazabilidad!$B$7:$B$134,"Matriz de riesgos") -> 2 | G36: Documento revisado | H36: Alex Mendoza Morante | I36: Víctor Tello Bravo | J36: Highest | K36: 46296 | M36: Documento de Visión | N36: En proceso | O36: Parcial | P36: 1.0 | Q36: Proyecto SCRUM | R36: Repositorio principal | S36: Completar la consolidación y revisión cruzada antes del 03/10/2026.
A37: EV-028 | B37: Trazabilidad | C37: Trazabilidad del MVP | D37: Relación entre requisito, historia, tarea Jira, pantalla, servicio, prueba y evidencia final. | E37: =COUNTIFS(Trazabilidad!$F$7:$F$134,$A37,Trazabilidad!$B$7:$B$134,"Matriz de calidad") -> 2 | F37: =COUNTIFS(Trazabilidad!$F$7:$F$134,$A37,Trazabilidad!$B$7:$B$134,"Matriz de riesgos") -> 1 | G37: Matriz de trazabilidad | H37: Víctor Tello Bravo | I37: Luis Rodríguez Barrera | J37: Highest | K37: 46296 | M37: Documentos / Evidencias/EV-028 | N37: En proceso | O37: Parcial | P37: 1.0 | Q37: Proyecto SCRUM | R37: Repositorio principal | S37: Completar vínculos faltantes de pruebas y evidencias antes del 03/10/2026.
A38: EV-029 | B38: Procesos | C38: Modelos BPMN vigentes | D38: Diagramas del proceso general, registro, acceso, recuperación y comparación con los flujos implementados. | E38: =COUNTIFS(Trazabilidad!$F$7:$F$134,$A38,Trazabilidad!$B$7:$B$134,"Matriz de calidad") -> 1 | F38: =COUNTIFS(Trazabilidad!$F$7:$F$134,$A38,Trazabilidad!$B$7:$B$134,"Matriz de riesgos") -> 1 | G38: BPMN y revisión | H38: Kevin Carriel Bonoso | I38: Víctor Tello Bravo | J38: High | K38: 46296 | L38: 46296 | M38: Documentos / BPMN | N38: Verificada | O38: Conforme | P38: 1.0 | Q38: Proyecto SCRUM | R38: Repositorio principal | S38: Los modelos representan el comportamiento aprobado del MVP.
A39: EV-030 | B39: Cambios | C39: Plan y registros de control de cambios | D39: Formato, análisis de impacto, decisión, responsable, evidencia de implementación y cierre de cambios relevantes. | E39: =COUNTIFS(Trazabilidad!$F$7:$F$134,$A39,Trazabilidad!$B$7:$B$134,"Matriz de calidad") -> 1 | F39: =COUNTIFS(Trazabilidad!$F$7:$F$134,$A39,Trazabilidad!$B$7:$B$134,"Matriz de riesgos") -> 1 | G39: Formato y registro | H39: Víctor Tello Bravo | I39: Alex Mendoza Morante | J39: Highest | K39: 46296 | L39: 46296 | M39: Gestión de cambios | N39: Verificada | O39: Conforme | P39: 1.0 | Q39: Proyecto SCRUM | R39: Repositorio principal | S39: Los cambios revisados cuentan con registro y decisión antes de incorporarse.
A40: EV-031 | B40: Entrega | C40: Lista y validación de entregables | D40: Inventario de archivos, versiones, enlaces, responsables y prueba de apertura previa a la entrega. | E40: =COUNTIFS(Trazabilidad!$F$7:$F$134,$A40,Trazabilidad!$B$7:$B$134,"Matriz de calidad") -> 0 | F40: =COUNTIFS(Trazabilidad!$F$7:$F$134,$A40,Trazabilidad!$B$7:$B$134,"Matriz de riesgos") -> 1 | G40: Lista de verificación | H40: Alex Mendoza Morante | I40: Luis Rodríguez Barrera | J40: Highest | K40: 46296 | M40: Documentos / Entrega final | N40: En proceso | O40: Parcial | P40: 1.0 | Q40: Proyecto SCRUM | R40: Repositorio principal | S40: Validar integridad y apertura de todos los archivos finales en la fecha de entrega; conservar acta o lista firmada.
A41: EV-032 | B41: Demostración | C41: Ambiente, datos y guion de demostración | D41: README de instalación, variables requeridas, datos ficticios, cuentas de prueba, ensayo y respaldo visual de la demostración. | E41: =COUNTIFS(Trazabilidad!$F$7:$F$134,$A41,Trazabilidad!$B$7:$B$134,"Matriz de calidad") -> 1 | F41: =COUNTIFS(Trazabilidad!$F$7:$F$134,$A41,Trazabilidad!$B$7:$B$134,"Matriz de riesgos") -> 2 | G41: Ensayo y guía | H41: Kevin Carriel Bonoso | I41: Alex Mendoza Morante | J41: Highest | K41: 46296 | M41: GitHub / Evidencias/EV-032 | N41: En proceso | O41: Parcial | P41: 1.0 | Q41: Proyecto SCRUM | R41: Repositorio principal | S41: Ensayar en un equipo alterno y preparar respaldo antes del 03/10/2026.
A42: EV-033 | B42: Seguridad | C42: Registro de eventos y auditoría | D42: Logs o tabla de auditoría con fecha, usuario y evento, sin contraseñas ni información sensible. | E42: =COUNTIFS(Trazabilidad!$F$7:$F$134,$A42,Trazabilidad!$B$7:$B$134,"Matriz de calidad") -> 1 | F42: =COUNTIFS(Trazabilidad!$F$7:$F$134,$A42,Trazabilidad!$B$7:$B$134,"Matriz de riesgos") -> 0 | G42: Revisión de logs | H42: Luis Ramírez Conejo | I42: Luis Rodríguez Barrera | J42: High | K42: 46296 | M42: Jira / Evidencias/EV-033 | N42: En proceso | O42: Parcial | P42: 1.0 | Q42: Proyecto SCRUM | R42: Repositorio principal | S42: Completar la cobertura de operaciones relevantes antes del 03/10/2026.
A43: EV-034 | B43: Solicitudes | C43: Alta y ubicación de solicitudes | D43: Formulario, selección de ubicación, validaciones, persistencia y correo al solicitante; casos válidos e inválidos. | E43: =COUNTIFS(Trazabilidad!$F$7:$F$134,$A43,Trazabilidad!$B$7:$B$134,"Matriz de calidad") -> 0 | F43: =COUNTIFS(Trazabilidad!$F$7:$F$134,$A43,Trazabilidad!$B$7:$B$134,"Matriz de riesgos") -> 0 | G43: Prueba integral | H43: Luis Ramírez Conejo | I43: Luis Rodríguez Barrera | J43: Highest | K43: 46297 | M43: Código por integrar en el repositorio: BS/views_solicitudes.py; BS/forms_solicitudes.py; BS/models.py | N43: Pendiente | O43: No aplica | P43: 1.1 | Q43: Por vincular | R43: Commit pendiente | S43: Prueba prevista: Crear solicitud válida, rechazar datos inválidos, guardar ubicación y verificar acuse por correo. Falta adjuntar resultado y fecha.
A44: EV-035 | B44: Solicitudes | C44: Consulta, edición y cancelación | D44: Mis solicitudes, detalle, estados, edición y cancelación; verificar pertenencia y URL inexistente o manipulada. | E44: =COUNTIFS(Trazabilidad!$F$7:$F$134,$A44,Trazabilidad!$B$7:$B$134,"Matriz de calidad") -> 0 | F44: =COUNTIFS(Trazabilidad!$F$7:$F$134,$A44,Trazabilidad!$B$7:$B$134,"Matriz de riesgos") -> 0 | G44: Prueba funcional y seguridad | H44: Luis Ramírez Conejo | I44: Luis Rodríguez Barrera | J44: Highest | K44: 46297 | M44: Código por integrar en el repositorio: BS/views_solicitudes.py; BS/urls_perfil.py | N44: Pendiente | O44: No aplica | P44: 1.1 | Q44: Por vincular | R44: Commit pendiente | S44: Prueba prevista: Consultar, editar y cancelar solicitud propia; bloquear acceso ajeno y URL inexistente con respuesta controlada. Falta adjuntar resultado y fecha.
...

Sheet Trazabilidad
A2: Trazabilidad entre calidad, riesgos y evidencias
A3: Relación individual de los 118 registros de origen con el paquete de evidencia que permite verificarlos.
A6: Código origen | B6: Fuente | C6: Categoría | D6: Criterio o riesgo | E6: Indicador / alerta | F6: Código evidencia | G6: Responsable | H6: Prioridad | I6: Resultado / estado | J6: Evidencia registrada | K6: Fecha revisión | L6: Observación
A7: CAL-001 | B7: Matriz de calidad | C7: Funcionalidad | D7: Portal público | E7: Se visualizan propósito, funcionamiento, usuarios, beneficios y contacto. | F7: EV-002 | G7: Víctor Tello Bravo | H7: High | I7: Cumple | J7: Capturas del portal y revisión funcional del contenido publicado. | K7: 46291 | L7: El criterio fue verificado y no se identificaron desviaciones relevantes.
A8: CAL-002 | B8: Matriz de calidad | C8: Funcionalidad | D8: Navegación pública | E8: El 100 % de enlaces principales funciona. | F8: EV-002 | G8: Mario Luzardo Fierro | H8: High | I8: Cumple | J8: Prueba de enlaces principales y capturas de navegación. | K8: 46291 | L8: El criterio fue verificado y no se identificaron desviaciones relevantes.
A9: CAL-003 | B9: Matriz de calidad | C9: Funcionalidad | D9: Registro de usuarios | E9: La cuenta se almacena cuando los datos son válidos. | F9: EV-003 | G9: Luis Rodríguez Barrera | H9: Highest | I9: Cumple | J9: Registro de cuenta, consulta en MySQL y captura de confirmación. | K9: 46291 | L9: El criterio fue verificado y no se identificaron desviaciones relevantes.
A10: CAL-004 | B10: Matriz de calidad | C10: Funcionalidad | D10: Validación de registro | E10: Los campos obligatorios y formatos inválidos generan mensajes. | F10: EV-003 | G10: Luis Rodríguez Barrera | H10: Highest | I10: Cumple | J10: Pruebas con campos vacíos, formatos inválidos y mensajes mostrados. | K10: 46291 | L10: El criterio fue verificado y no se identificaron desviaciones relevantes.
A11: CAL-005 | B11: Matriz de calidad | C11: Funcionalidad | D11: Correo único | E11: El sistema rechaza un correo previamente registrado. | F11: EV-003 | G11: Luis Ramírez Conejo | H11: High | I11: Cumple | J11: Prueba de duplicidad con un correo previamente registrado. | K11: 46291 | L11: El criterio fue verificado y no se identificaron desviaciones relevantes.
A12: CAL-006 | B12: Matriz de calidad | C12: Funcionalidad | D12: Inicio de sesión | E12: Se crea una sesión y se permite acceder al panel. | F12: EV-004 | G12: Luis Rodríguez Barrera | H12: Highest | I12: Cumple | J12: Caso de prueba con credenciales válidas y captura de la sesión iniciada. | K12: 46291 | L12: El criterio fue verificado y no se identificaron desviaciones relevantes.
A13: CAL-007 | B13: Matriz de calidad | C13: Funcionalidad | D13: Credenciales incorrectas | E13: No se crea una sesión y se muestra un mensaje comprensible. | F13: EV-004 | G13: Luis Rodríguez Barrera | H13: Highest | I13: Cumple | J13: Prueba negativa con contraseña incorrecta y mensaje controlado. | K13: 46291 | L13: El criterio fue verificado y no se identificaron desviaciones relevantes.
A14: CAL-008 | B14: Matriz de calidad | C14: Funcionalidad | D14: Cierre de sesión | E14: El panel queda inaccesible después de cerrar sesión. | F14: EV-004 | G14: Kevin Carriel Bonoso | H14: Highest | I14: Cumple | J14: Prueba de cierre y acceso directo posterior a una ruta privada. | K14: 46291 | L14: El criterio fue verificado y no se identificaron desviaciones relevantes.
A15: CAL-009 | B15: Matriz de calidad | C15: Funcionalidad | D15: Recuperación de contraseña | E15: El sistema procesa un correo registrado y presenta confirmación. | F15: EV-005 | G15: Mario Luzardo Fierro | H15: High | I15: Cumple parcialmente | J15: Correo de recuperación, enlace generado y pantalla de confirmación. | K15: 46291 | L15: Validación integral pendiente según el paquete de evidencia vinculado.
A16: CAL-010 | B16: Matriz de calidad | C16: Funcionalidad | D16: Cambio de contraseña | E16: La nueva clave funciona y la anterior queda invalidada. | F16: EV-005 | G16: Luis Ramírez Conejo | H16: High | I16: Cumple parcialmente | J16: Prueba de actualización, limpieza del formulario y nuevo acceso. | K16: 46291 | L16: Validación integral pendiente según el paquete de evidencia vinculado.
A17: CAL-011 | B17: Matriz de calidad | C17: Funcionalidad | D17: Panel principal | E17: Se muestran nombre, rol y opciones autorizadas. | F17: EV-006 | G17: Víctor Tello Bravo | H17: High | I17: Cumple | J17: Captura del panel con usuario autenticado y opciones habilitadas. | K17: 46291 | L17: El criterio fue verificado y no se identificaron desviaciones relevantes.
A18: CAL-012 | B18: Matriz de calidad | C18: Funcionalidad | D18: Perfil básico | E18: Los cambios válidos se almacenan correctamente. | F18: EV-007 | G18: Luis Rodríguez Barrera | H18: High | I18: Cumple | J18: Prueba de consulta y actualización de datos permitidos. | K18: 46291 | L18: El criterio fue verificado y no se identificaron desviaciones relevantes.
... A124: RIE-054 | B124: Matriz de riesgos | C124: Demostración | D124: Ausencia de datos de prueba | E124: No hay usuario válido para el recorrido | F124: EV-032 | G124: Luis Rodríguez Barrera | H124: Low | I124: Cerrado | J124: Guion, datos de prueba y ensayo del ambiente de demostración. | K124: 46296 | L124: No se detectó el indicador de alerta después de aplicar el control; el riesgo se cierra con evidencia disponible.
A125: DJ-001 | B125: Flujos Django | C125: Solicitudes | D125: Alta y ubicación de solicitudes | E125: Formulario, selección de ubicación, validaciones, persistencia y correo al solicitante; casos válidos e inválidos. | F125: EV-034 | G125: Luis Ramírez Conejo | H125: Highest | I125: Pendiente | J125: Caso previsto: Crear solicitud válida, rechazar datos inválidos, guardar ubicación y verificar acuse por correo. | L125: Código de referencia: BS/views_solicitudes.py; BS/forms_solicitudes.py; BS/models.py. Ejecución y resultado pendientes; no marcar como conforme sin reporte.
A126: DJ-002 | B126: Flujos Django | C126: Solicitudes | D126: Consulta, edición y cancelación | E126: Mis solicitudes, detalle, estados, edición y cancelación; verificar pertenencia y URL inexistente o manipulada. | F126: EV-035 | G126: Luis Ramírez Conejo | H126: Highest | I126: Pendiente | J126: Caso previsto: Consultar, editar y cancelar solicitud propia; bloquear acceso ajeno y URL inexistente con respuesta controlada. | L126: Código de referencia: BS/views_solicitudes.py; BS/urls_perfil.py. Ejecución y resultado pendientes; no marcar como conforme sin reporte.
A127: DJ-003 | B127: Flujos Django | C127: Voluntariado | D127: Panel y postulación de voluntarios | E127: Listado elegible, detalle, distancias, postulación, retiro y mensajes; probar permisos y datos persistidos. | F127: EV-036 | G127: Luis Ramírez Conejo | H127: High | I127: Pendiente | J127: Caso previsto: Ver solicitudes elegibles, postular, retirar y contrastar estado y distancia con datos de prueba. | L127: Código de referencia: BS/views_voluntariado.py; BS/forms_voluntariado.py. Ejecución y resultado pendientes; no marcar como conforme sin reporte.
A128: DJ-004 | B128: Flujos Django | C128: Coordinación | D128: Revisión y asignación de solicitudes | E128: Bandeja, decisiones, postulaciones, asignación, auditoría y avisos; comprobar estados y permisos del coordinador. | F128: EV-037 | G128: Kevin Carriel Bonoso | H128: Highest | I128: Pendiente | J128: Caso previsto: Revisar bandeja, aprobar, asignar y comprobar permisos, historial y notificaciones. | L128: Código de referencia: BS/views_coordinacion.py; BS/forms_coordinacion.py. Ejecución y resultado pendientes; no marcar como conforme sin reporte.
A129: DJ-005 | B129: Flujos Django | C129: Contacto | D129: Casos de contacto y actuaciones | E129: Registro, acuse de recibo, revisión por administrador o moderador, nota, historial con fecha y actor, y correo de actualización. | F129: EV-038 | G129: Luis Ramírez Conejo | H129: High | I129: Pendiente | J129: Caso previsto: Registrar caso, recibir acuse, cambiar estado, guardar actuación y verificar nota del correo. | L129: Código de referencia: BS/views_contacto.py; BS/services_contacto.py; BS/forms_contacto.py. Ejecución y resultado pendientes; no marcar como conforme sin reporte.
A130: DJ-006 | B130: Flujos Django | C130: Administración | D130: Usuarios, roles y catálogos | E130: Alta por administrador, correo de activación, asignación y aprobación de roles, gestión de permisos y catálogos; pruebas de acceso directo. | F130: EV-039 | G130: Kevin Carriel Bonoso | H130: Highest | I130: Pendiente | J130: Caso previsto: Alta y activación administrativa; añadir rol, modificar permisos y catálogos; bloquear acceso ajeno. | L130: Código de referencia: BS/views_usuarios.py; BS/views_roles.py; BS/views_catalogos.py. Ejecución y resultado pendientes; no marcar como conforme sin reporte.
A131: DJ-007 | B131: Flujos Django | C131: Portal público | D131: Instituciones avaladas y carrusel | E131: Alta, imagen recortada, enlace y visualización de instituciones; navegación circular con flechas y puntos. | F131: EV-040 | G131: Mario Luzardo Fierro | H131: High | I131: Pendiente | J131: Caso previsto: Crear institución, recortar imagen y comprobar tarjetas, enlace y navegación del carrusel. | L131: Código de referencia: BS/views_instituciones.py; BS/templates/instituciones/. Ejecución y resultado pendientes; no marcar como conforme sin reporte.
A132: DJ-008 | B132: Flujos Django | C132: Acceso | D132: Activación, correo y acceso social | E132: Registro local, reenvío, enlace caducado, confirmación por correo tras login, y Google y Microsoft con cuenta habilitada. | F132: EV-041 | G132: Luis Ramírez Conejo | H132: Highest | I132: Pendiente | J132: Caso previsto: Activar, reenviar, caducar enlace y verificar inicio local, Google y Microsoft con confirmación por correo. | L132: Código de referencia: BS/views_cuentas.py; BS/views_social.py; BS/social_adapter.py. Ejecución y resultado pendientes; no marcar como conforme sin reporte.
A133: DJ-009 | B133: Flujos Django | C133: Privacidad | D133: Aceptación de datos personales | E133: Primer acceso local y social, enlace público, aceptación expresa, fecha y hora guardadas y bloqueo hasta consentir. | F133: EV-042 | G133: Luis Rodríguez Barrera | H133: High | I133: Pendiente | J133: Caso previsto: Primer acceso local y social, abrir ley en otra pestaña y comprobar fecha y hora de aceptación. | L133: Código de referencia: BS/views_perfil.py; BS/templates/cuentas/aceptar_datos_personales.html. Ejecución y resultado pendientes; no marcar como conforme sin reporte.
A134: DJ-010 | B134: Flujos Django | C134: Accesibilidad | D134: Opciones de accesibilidad de ambos paneles | E134: Comprobar teclado, foco, contraste, lectura en voz, texto ampliado y persistencia en topbar y panel para distintos roles. | F134: EV-043 | G134: Mario Luzardo Fierro | H134: High | I134: Pendiente | J134: Caso previsto: Probar teclado, foco, contraste y lectura en voz en portal y panel; registrar resultados por navegador. | L134: Código de referencia: BS/templates/componentes/accesibilidad_panel.html; BS/static/. Ejecución y resultado pendientes; no marcar como conforme sin reporte.

Sheet Catálogos
A1: Estado evidencia | B1: Resultado | C1: Tipo | D1: Prioridad | E1: Responsable
A2: Pendiente | B2: Conforme | C2: Documento y registro | D2: Highest | E2: Alex Mendoza Morante
A3: En proceso | B3: Parcial | C3: Capturas y prueba funcional | D3: High | E3: Víctor Tello Bravo
A4: Verificada | B4: No conforme | C4: Prueba integral | D4: Low | E4: Kevin Carriel Bonoso
A5: No aplica | B5: No aplica | C5: Revisión técnica y prueba | D5: Lowest | E5: Mario Luzardo Fierro
C6: Pruebas negativas | E6: Luis Ramírez Conejo
C7: Lista de comprobación | E7: Luis Rodríguez Barrera
C8: Consulta y respaldo
C9: Matriz de control
C10: Ensayo y guía
