Workbook

Sheet Resumen
B2: BARRIO SOLIDARIO · Matriz de pruebas realizadas
B3: Resultados consolidados del MVP al 01/10/2026. Los casos sin evidencia verificable permanecen pendientes y no se contabilizan como aprobados.
B5: Indicador | C5: Resultado | D5: Interpretación | F5: Tipo | G5: Ejecutadas | H5: Cumple | I5: Parcial | J5: Pendiente
B6: Total de casos | C6: =COUNTA('Pruebas realizadas'!A10:A84) -> 74 | D6: Casos registrados | F6: Funcional positiva | G6: =COUNTIFS('Pruebas realizadas'!$C$10:$C$84,$F6,'Pruebas realizadas'!$J$10:$J$84,"Ejecutada") -> 16 | H6: =COUNTIFS('Pruebas realizadas'!$C$10:$C$84,$F6,'Pruebas realizadas'!$K$10:$K$84,"Cumple") -> 15 | I6: =COUNTIFS('Pruebas realizadas'!$C$10:$C$84,$F6,'Pruebas realizadas'!$K$10:$K$84,"Cumple parcialmente") -> 1 | J6: =COUNTIFS('Pruebas realizadas'!$C$10:$C$84,$F6,'Pruebas realizadas'!$J$10:$J$84,"Pendiente") -> 0
B7: Casos ejecutados | C7: =COUNTIF('Pruebas realizadas'!J10:J84,"Ejecutada") -> 64 | D7: Cuentan con resultado obtenido | F7: Funcional negativa | G7: =COUNTIFS('Pruebas realizadas'!$C$10:$C$84,$F7,'Pruebas realizadas'!$J$10:$J$84,"Ejecutada") -> 9 | H7: =COUNTIFS('Pruebas realizadas'!$C$10:$C$84,$F7,'Pruebas realizadas'!$K$10:$K$84,"Cumple") -> 9 | I7: =COUNTIFS('Pruebas realizadas'!$C$10:$C$84,$F7,'Pruebas realizadas'!$K$10:$K$84,"Cumple parcialmente") -> 0 | J7: =COUNTIFS('Pruebas realizadas'!$C$10:$C$84,$F7,'Pruebas realizadas'!$J$10:$J$84,"Pendiente") -> 0
B8: Pendientes | C8: =COUNTIF('Pruebas realizadas'!J10:J84,"Pendiente") -> 10 | D8: Aún requieren ejecución y evidencia | F8: Seguridad | G8: =COUNTIFS('Pruebas realizadas'!$C$10:$C$84,$F8,'Pruebas realizadas'!$J$10:$J$84,"Ejecutada") -> 6 | H8: =COUNTIFS('Pruebas realizadas'!$C$10:$C$84,$F8,'Pruebas realizadas'!$K$10:$K$84,"Cumple") -> 4 | I8: =COUNTIFS('Pruebas realizadas'!$C$10:$C$84,$F8,'Pruebas realizadas'!$K$10:$K$84,"Cumple parcialmente") -> 2 | J8: =COUNTIFS('Pruebas realizadas'!$C$10:$C$84,$F8,'Pruebas realizadas'!$J$10:$J$84,"Pendiente") -> 2
B9: Cumplen | C9: =COUNTIF('Pruebas realizadas'!K10:K84,"Cumple") -> 59 | D9: Resultado esperado alcanzado | F9: Accesibilidad | G9: =COUNTIFS('Pruebas realizadas'!$C$10:$C$84,$F9,'Pruebas realizadas'!$J$10:$J$84,"Ejecutada") -> 8 | H9: =COUNTIFS('Pruebas realizadas'!$C$10:$C$84,$F9,'Pruebas realizadas'!$K$10:$K$84,"Cumple") -> 7 | I9: =COUNTIFS('Pruebas realizadas'!$C$10:$C$84,$F9,'Pruebas realizadas'!$K$10:$K$84,"Cumple parcialmente") -> 1 | J9: =COUNTIFS('Pruebas realizadas'!$C$10:$C$84,$F9,'Pruebas realizadas'!$J$10:$J$84,"Pendiente") -> 1
B10: Cumplen parcialmente | C10: =COUNTIF('Pruebas realizadas'!K10:K84,"Cumple parcialmente") -> 5 | D10: Requieren ajuste o revalidación | F10: Compatibilidad | G10: =COUNTIFS('Pruebas realizadas'!$C$10:$C$84,$F10,'Pruebas realizadas'!$J$10:$J$84,"Ejecutada") -> 2 | H10: =COUNTIFS('Pruebas realizadas'!$C$10:$C$84,$F10,'Pruebas realizadas'!$K$10:$K$84,"Cumple") -> 2 | I10: =COUNTIFS('Pruebas realizadas'!$C$10:$C$84,$F10,'Pruebas realizadas'!$K$10:$K$84,"Cumple parcialmente") -> 0 | J10: =COUNTIFS('Pruebas realizadas'!$C$10:$C$84,$F10,'Pruebas realizadas'!$J$10:$J$84,"Pendiente") -> 0
B11: No cumplen | C11: =COUNTIF('Pruebas realizadas'!K10:K84,"No cumple") -> 0 | D11: Resultado no aceptable | F11: Rendimiento | G11: =COUNTIFS('Pruebas realizadas'!$C$10:$C$84,$F11,'Pruebas realizadas'!$J$10:$J$84,"Ejecutada") -> 2 | H11: =COUNTIFS('Pruebas realizadas'!$C$10:$C$84,$F11,'Pruebas realizadas'!$K$10:$K$84,"Cumple") -> 2 | I11: =COUNTIFS('Pruebas realizadas'!$C$10:$C$84,$F11,'Pruebas realizadas'!$K$10:$K$84,"Cumple parcialmente") -> 0 | J11: =COUNTIFS('Pruebas realizadas'!$C$10:$C$84,$F11,'Pruebas realizadas'!$J$10:$J$84,"Pendiente") -> 0
B12: Porcentaje ejecutado | C12: =IFERROR(C7/C6,0) -> 0.86486486 | D12: Cobertura de ejecución | F12: Integración | G12: =COUNTIFS('Pruebas realizadas'!$C$10:$C$84,$F12,'Pruebas realizadas'!$J$10:$J$84,"Ejecutada") -> 1 | H12: =COUNTIFS('Pruebas realizadas'!$C$10:$C$84,$F12,'Pruebas realizadas'!$K$10:$K$84,"Cumple") -> 0 | I12: =COUNTIFS('Pruebas realizadas'!$C$10:$C$84,$F12,'Pruebas realizadas'!$K$10:$K$84,"Cumple parcialmente") -> 1 | J12: =COUNTIFS('Pruebas realizadas'!$C$10:$C$84,$F12,'Pruebas realizadas'!$J$10:$J$84,"Pendiente") -> 1
B13: Porcentaje de conformidad | C13: =IFERROR((C9+C10*0.5)/(C7),0) -> 0.9609375 | D13: Cumplimiento ponderado sobre ejecutados
B16: Criterios de interpretación
B17: 1. | C17: Cumple: el resultado obtenido coincide con el resultado esperado y existe una evidencia asociada.
B18: 2. | C18: Cumple parcialmente: el flujo funciona, pero requiere completar cobertura, corregir un hallazgo o ejecutar revalidación.
B19: 3. | C19: Pendiente: el caso se encuentra definido, pero no existe una ejecución verificable; no debe presentarse como aprobado.
B20: 4. | C20: Los datos utilizados deben ser ficticios y las capturas no deben mostrar contraseñas, tokens, archivos .env ni información personal real.
B23: Jira | C23: https://uees-team-kgpqd887.atlassian.net/jira/software/projects/SCRUM/summary
B24: GitHub | C24: https://github.com/UESSalexmendoza/Proyecto-Ingenieria-II/tree/main

Sheet Pruebas realizadas
A2: Registro de pruebas ejecutadas y pendientes del MVP
A3: Un registro por caso. Los estados, resultados y responsables se pueden actualizar mediante listas vinculadas a Catálogos.
A5: Total | B5: Ejecutadas | C5: Pendientes | D5: Cumple | E5: Parcial | F5: No cumple | G5: Defectos abiertos | H5: Estado general
A6: =COUNTA(A10:A84) -> 74 | B6: =COUNTIF(J10:J84,"Ejecutada") -> 64 | C6: =COUNTIF(J10:J84,"Pendiente") -> 10 | D6: =COUNTIF(K10:K84,"Cumple") -> 59 | E6: =COUNTIF(K10:K84,"Cumple parcialmente") -> 5 | F6: =COUNTIF(K10:K84,"No cumple") -> 0 | G6: =COUNTA('Defectos y revalidación'!A7:A11) -> 5 | H6: =IF(F6>0,"NO APROBADO",IF(E6>0,"EN SEGUIMIENTO",IF(C6>0,"PENDIENTE","CONFORME"))) -> EN SEGUIMIENTO
A9: Código | B9: Módulo | C9: Tipo de prueba | D9: Escenario | E9: Precondición | F9: Datos de prueba | G9: Pasos principales | H9: Resultado esperado | I9: Resultado obtenido | J9: Estado ejecución | K9: Resultado | L9: Prioridad | M9: Responsable | N9: Fecha ejecución | O9: Evidencia | P9: Riesgo relacionado | Q9: Defecto | R9: Revalidación | S9: Observación
A10: PR-001 | B10: Portal público | C10: Funcional positiva | D10: Carga de página principal | E10: Servidor local iniciado | F10: URL principal | G10: Abrir el portal y revisar las secciones visibles. | H10: Mostrar propósito, funcionamiento, beneficios y contacto. | I10: El portal cargó y presentó el contenido previsto. | J10: Ejecutada | K10: Cumple | L10: High | M10: Víctor Tello Bravo | N10: 46291 | O10: EV-002 | P10: Demostración poco clara | R10: No requerida
A11: PR-002 | B11: Portal público | C11: Funcional positiva | D11: Navegación a Términos y condiciones | E11: Portal disponible | F11: Enlace Legal | G11: Seleccionar Términos desde el menú. | H11: Abrir la página correcta sin error. | I11: La página se abrió correctamente. | J11: Ejecutada | K11: Cumple | L11: High | M11: Mario Luzardo Fierro | N11: 46291 | O11: EV-002 | P11: Límites ambiguos del MVP | R11: No requerida
A12: PR-003 | B12: Portal público | C12: Funcional positiva | D12: Navegación a Privacidad | E12: Portal disponible | F12: Enlace Privacidad | G12: Seleccionar Privacidad desde el menú. | H12: Abrir la política de privacidad. | I12: El enlace dirigió al contenido esperado. | J12: Ejecutada | K12: Cumple | L12: High | M12: Mario Luzardo Fierro | N12: 46291 | O12: EV-002 | P12: Recolección excesiva de datos | R12: No requerida
A13: PR-004 | B13: Portal público | C13: Funcional positiva | D13: Enlaces de contacto e información | E13: Portal disponible | F13: Enlaces principales | G13: Recorrer los enlaces del encabezado y pie. | H13: Todos los enlaces deben responder. | I13: No se encontraron enlaces bloqueantes. | J13: Ejecutada | K13: Cumple | L13: Low | M13: Mario Luzardo Fierro | N13: 46291 | O13: EV-002 | P13: Demostración poco clara | R13: No requerida
A14: PR-005 | B14: Portal público | C14: Interfaz | D14: Consistencia de encabezado y pie | E14: Varias páginas públicas disponibles | F14: Páginas públicas | G14: Comparar logo, navegación, tamaños y pie. | H14: Mantener estructura visual uniforme. | I14: Los componentes comunes conservaron el mismo diseño. | J14: Ejecutada | K14: Cumple | L14: High | M14: Mario Luzardo Fierro | N14: 46291 | O14: EV-016 | P14: Encabezado inconsistente | R14: No requerida
A15: PR-006 | B15: Registro | C15: Funcional positiva | D15: Registro con datos válidos | E15: Correo no registrado | F15: Nombre, correo, teléfono y clave válidos | G15: Completar el formulario, aceptar políticas y enviar. | H15: Crear cuenta pendiente y enviar activación. | I15: La cuenta fue almacenada en estado pendiente. | J15: Ejecutada | K15: Cumple | L15: Highest | M15: Luis Ramírez Conejo | N15: 46291 | O15: EV-003 | P15: Falla en el registro de usuarios | R15: No requerida
A16: PR-007 | B16: Registro | C16: Funcional negativa | D16: Campos obligatorios vacíos | E16: Formulario abierto | F16: Campos vacíos | G16: Enviar el formulario sin completar datos. | H16: Rechazar y señalar los campos requeridos. | I16: Se mostraron mensajes junto a los campos obligatorios. | J16: Ejecutada | K16: Cumple | L16: Highest | M16: Luis Rodríguez Barrera | N16: 46291 | O16: EV-003 | P16: Falla en el registro de usuarios | R16: No requerida
A17: PR-008 | B17: Registro | C17: Funcional negativa | D17: Correo con formato inválido | E17: Formulario abierto | F17: usuario@ | G17: Completar el resto y enviar. | H17: Rechazar el correo y conservar los datos permitidos. | I17: El sistema rechazó el formato inválido. | J17: Ejecutada | K17: Cumple | L17: High | M17: Luis Rodríguez Barrera | N17: 46291 | O17: EV-003 | P17: Inyección o manipulación de entradas | R17: No requerida
A18: PR-009 | B18: Registro | C18: Validación | D18: Nombres admiten solo caracteres permitidos | E18: Formulario abierto | F18: Nombre con números y símbolos | G18: Enviar datos inválidos. | H18: Rechazar caracteres no permitidos. | I18: El campo presentó validación controlada. | J18: Ejecutada | K18: Cumple | L18: High | M18: Luis Rodríguez Barrera | N18: 46291 | O18: EV-003 | P18: Inyección o manipulación de entradas | R18: No requerida
A19: PR-010 | B19: Registro | C19: Validación | D19: Teléfono admite solo números | E19: Formulario abierto | F19: Teléfono con letras | G19: Enviar formulario. | H19: Rechazar caracteres no numéricos. | I19: El dato inválido no fue aceptado. | J19: Ejecutada | K19: Cumple | L19: High | M19: Luis Rodríguez Barrera | N19: 46291 | O19: EV-003 | P19: Inyección o manipulación de entradas | R19: No requerida
A20: PR-011 | B20: Registro | C20: Funcional negativa | D20: Correo duplicado | E20: Existe una cuenta previa | F20: Correo previamente registrado | G20: Intentar crear otra cuenta con el mismo correo. | H20: Rechazar la duplicidad. | I20: El sistema informó que el correo ya estaba registrado. | J20: Ejecutada | K20: Cumple | L20: Highest | M20: Luis Ramírez Conejo | N20: 46291 | O20: EV-017 | P20: Usuarios duplicados | R20: No requerida
A21: PR-012 | B21: Registro | C21: Seguridad | D21: Longitud máxima de contraseña | E21: Formulario abierto | F21: Clave mayor a 15 caracteres | G21: Intentar registrar la cuenta. | H21: Aplicar la regla definida y mostrar orientación. | I21: La validación impidió guardar una clave fuera de la regla. | J21: Ejecutada | K21: Cumple | L21: High | M21: Luis Rodríguez Barrera | N21: 46292 | O21: EV-008 | P21: Contraseñas almacenadas en texto plano | R21: No requerida
... A36: PR-027 | B36: Recuperación | C36: Seguridad negativa | D36: Solicitud con correo inexistente | E36: Cuenta inexistente | F36: Correo no registrado | G36: Solicitar recuperación. | H36: Mostrar respuesta general sin revelar existencia. | I36: La respuesta fue controlada y equivalente. | J36: Ejecutada | K36: Cumple | L36: High | M36: Luis Rodríguez Barrera | N36: 46292 | O36: EV-009 | P36: Errores revelan información sensible | R36: No requerida
A37: PR-028 | B37: Recuperación | C37: Funcional positiva | D37: Cambio con token vigente | E37: Solicitud previa válida | F37: Token vigente y clave válida | G37: Abrir enlace y guardar nueva clave. | H37: Actualizar la contraseña. | I37: El flujo funciona, pero falta cerrar evidencia de caducidad y notificación. | J37: Ejecutada | K37: Cumple parcialmente | L37: High | M37: Luis Ramírez Conejo | N37: 46293 | O37: EV-005 | P37: Recuperación de contraseña incompleta | Q37: DEF-001 | R37: Pendiente | S37: Completar revalidación integral antes del 03/10/2026.
A38: PR-029 | B38: Recuperación | C38: Funcional negativa | D38: Token inválido o manipulado | E38: Enlace modificado | F38: Token inválido | G38: Abrir el enlace alterado. | H38: Rechazar y permitir solicitar otro enlace. | I38: El sistema rechazó el token sin exponer trazas. | J38: Ejecutada | K38: Cumple | L38: High | M38: Luis Rodríguez Barrera | N38: 46293 | O38: EV-005 | P38: Recuperación de contraseña incompleta | R38: No requerida
A39: PR-030 | B39: Recuperación | C39: Seguridad | D39: Clave anterior queda invalidada | E39: Cambio exitoso | F39: Clave anterior y nueva | G39: Intentar acceso con ambas claves. | H39: Aceptar solo la nueva contraseña. | I39: La clave anterior dejó de funcionar. | J39: Ejecutada | K39: Cumple | L39: High | M39: Luis Rodríguez Barrera | N39: 46293 | O39: EV-005 | P39: Recuperación de contraseña incompleta | R39: No requerida
A40: PR-031 | B40: Perfil | C40: Funcional positiva | D40: Consulta del perfil | E40: Usuario autenticado | F40: Perfil existente | G40: Abrir personalización. | H40: Mostrar únicamente datos del usuario actual. | I40: Los datos correctos fueron presentados. | J40: Ejecutada | K40: Cumple | L40: High | M40: Luis Ramírez Conejo | N40: 46293 | O40: EV-007 | P40: Actualización incorrecta del perfil | R40: No requerida
A41: PR-032 | B41: Perfil | C41: Funcional positiva | D41: Actualización válida | E41: Usuario autenticado | F41: Teléfono y nombres válidos | G41: Editar y guardar. | H41: Persistir los cambios permitidos. | I41: Los datos se conservaron tras recargar. | J41: Ejecutada | K41: Cumple | L41: High | M41: Luis Ramírez Conejo | N41: 46293 | O41: EV-007 | P41: Pérdida de información | R41: No requerida
A42: PR-033 | B42: Perfil | C42: Funcional negativa | D42: Actualización con formato inválido | E42: Usuario autenticado | F42: Teléfono con letras | G42: Guardar cambios. | H42: Rechazar y explicar el error. | I42: No se modificó el dato persistido. | J42: Ejecutada | K42: Cumple | L42: High | M42: Luis Rodríguez Barrera | N42: 46293 | O42: EV-007 | P42: Actualización incorrecta del perfil | R42: No requerida
A43: PR-034 | B43: Perfil | C43: Seguridad negativa | D43: Acceso a perfil de otro usuario | E43: Dos cuentas existentes | F43: Identificador ajeno | G43: Modificar URL o petición. | H43: Denegar el acceso. | I43: La aplicación conservó el perfil del usuario autenticado. | J43: Ejecutada | K43: Cumple | L43: Highest | M43: Kevin Carriel Bonoso | N43: 46293 | O43: EV-006 | P43: Escalada de privilegios | R43: No requerida
A44: PR-035 | B44: Roles y permisos | C44: Seguridad | D44: Acciones autorizadas por rol | E44: Usuarios de distintos roles | F44: Cuentas de prueba | G44: Ingresar con cada rol y recorrer el panel. | H44: Mostrar solo opciones autorizadas. | I44: El control básico funciona; falta completar todos los roles proyectados. | J44: Ejecutada | K44: Cumple parcialmente | L44: Highest | M44: Kevin Carriel Bonoso | N44: 46293 | O44: EV-006 | P44: Panel incorrecto según el rol | Q44: DEF-002 | R44: Pendiente | S44: Completar matriz de permisos y revalidar antes del 02/10/2026.
A45: PR-036 | B45: Roles y permisos | C45: Seguridad negativa | D45: Ruta ajena al rol | E45: Usuario sin permiso | F45: URL protegida | G45: Acceder directamente. | H45: Responder con denegación o redirección. | I45: Las rutas verificadas rechazaron el acceso indebido. | J45: Ejecutada | K45: Cumple | L45: Highest | M45: Kevin Carriel Bonoso | N45: 46293 | O45: EV-006 | P45: Escalada de privilegios | R45: No requerida
A46: PR-037 | B46: Roles y permisos | C46: Interfaz | D46: Panel corresponde al rol | E46: Cuentas de prueba | F46: Roles del MVP | G46: Comparar menús y opciones. | H46: Presentar acciones coherentes con el rol. | I46: Los roles implementados muestran paneles diferenciados. | J46: Ejecutada | K46: Cumple | L46: High | M46: Víctor Tello Bravo | N46: 46293 | O46: EV-006 | P46: Panel incorrecto según el rol | R46: No requerida
A47: PR-038 | B47: Administración | C47: Seguridad | D47: Acceso de superusuario al administrador | E47: Superusuario creado | F47: Credenciales administrativas | G47: Abrir /admin e iniciar sesión. | H47: Permitir acceso solo al superusuario. | I47: El administrador fue accesible con la cuenta autorizada. | J47: Ejecutada | K47: Cumple | L47: Highest | M47: Kevin Carriel Bonoso | N47: 46293 | O47: EV-039 | P47: Acceso sin autenticación | R47: No requerida
A48: PR-039 | B48: Seguridad | C48: Seguridad negativa | D48: Validación del lado servidor | E48: Formulario disponible | F48: Petición modificada | G48: Enviar datos omitiendo controles HTML. | H48: Rechazar en Python. | I48: El servidor devolvió errores controlados. | J48: Ejecutada | K48: Cumple | L48: Highest | M48: Luis Rodríguez Barrera | N48: 46293 | O48: EV-009 | P48: Inyección o manipulación de entradas | R48: No requerida
A49: PR-040 | B49: Seguridad | C49: Seguridad negativa | D49: Manipulación e inyección básica | E49: Formularios disponibles | F49: Caracteres especiales y cargas de prueba | G49: Enviar entradas especiales. | H49: No alterar consultas ni datos. | I49: No se observaron modificaciones ni errores de base de datos. | J49: Ejecutada | K49: Cumple | L49: Highest | M49: Luis Rodríguez Barrera | N49: 46293 | O49: EV-009 | P49: Inyección o manipulación de entradas | R49: No requerida
A50: PR-041 | B50: Seguridad | C50: Seguridad negativa | D50: Errores sin información sensible | E50: Ambiente de prueba | F50: Petición inválida | G50: Provocar una validación controlada. | H50: No mostrar traceback, rutas ni consultas. | I50: La interfaz mostró un mensaje general. | J50: Ejecutada | K50: Cumple | L50: High | M50: Luis Rodríguez Barrera | N50: 46293 | O50: EV-009 | P50: Errores revelan información sensible | R50: No requerida
A51: PR-042 | B51: Seguridad | C51: Revisión técnica | D51: Secretos fuera del repositorio | E51: Repositorio disponible | F51: settings y archivos ignorados | G51: Revisar código e historial. | H51: No encontrar claves, tokens ni .env. | I51: No se detectaron credenciales versionadas. | J51: Ejecutada | K51: Cumple | L51: Highest | M51: Kevin Carriel Bonoso | N51: 46293 | O51: EV-010 | P51: Credenciales publicadas en Git | R51: No requerida
A52: PR-043 | B52: Seguridad | C52: Revisión técnica | D52: Contraseña almacenada como hash | E52: Cuenta de prueba creada | F52: Registro anonimizado | G52: Consultar el campo de contraseña. | H52: Observar hash no reversible. | I52: La base conserva el hash de Django. | J52: Ejecutada | K52: Cumple | L52: Highest | M52: Luis Rodríguez Barrera | N52: 46293 | O52: EV-008 | P52: Contraseñas almacenadas en texto plano | R52: No requerida
A53: PR-044 | B53: Privacidad | C53: Funcional positiva | D53: Aceptación de datos en cuenta local | E53: Primer acceso local | F53: Casilla y acción de aceptación | G53: Intentar continuar y luego aceptar. | H53: Bloquear hasta registrar consentimiento. | I53: La aceptación quedó registrada con fecha y hora. | J53: Ejecutada | K53: Cumple | L53: High | M53: Luis Rodríguez Barrera | N53: 46294 | O53: EV-042 | P53: Recolección excesiva de datos | R53: No requerida
A54: PR-045 | B54: Privacidad | C54: Funcional positiva | D54: Aceptación en cuenta social | E54: Cuenta social ya habilitada | F54: Usuario OAuth de prueba | G54: Iniciar por proveedor y aceptar política. | H54: Aplicar el mismo control que al acceso local. | I54: El control se presentó al primer acceso. | J54: Ejecutada | K54: Cumple | L54: High | M54: Luis Rodríguez Barrera | N54: 46294 | O54: EV-042 | P54: Recolección excesiva de datos | R54: No requerida
A55: PR-046 | B55: Privacidad | C55: Seguridad negativa | D55: Bloqueo sin consentimiento | E55: Usuario sin aceptación | F55: URL interna | G55: Intentar omitir la pantalla. | H55: Impedir continuar hasta aceptar. | I55: El acceso fue redirigido al consentimiento. | J55: Ejecutada | K55: Cumple | L55: High | M55: Luis Rodríguez Barrera | N55: 46294 | O55: EV-042 | P55: Acceso sin autenticación | R55: No requerida
A56: PR-047 | B56: Accesibilidad | C56: Accesibilidad | D56: Contraste de texto y controles | E56: Pantallas principales | F56: Colores institucionales | G56: Medir combinaciones relevantes. | H56: Cumplir 4.5:1 o 3:1 según tamaño. | I56: Los componentes revisados alcanzaron el criterio. | J56: Ejecutada | K56: Cumple | L56: Highest | M56: Mario Luzardo Fierro | N56: 46294 | O56: EV-012 | P56: Contraste insuficiente | R56: No requerida
A57: PR-048 | B57: Accesibilidad | C57: Accesibilidad | D57: Navegación del portal por teclado | E57: Portal cargado | F57: Tab, Enter y espacio | G57: Recorrer enlaces y botones. | H57: Acceder sin ratón. | I57: Los controles públicos fueron operables. | J57: Ejecutada | K57: Cumple | L57: Highest | M57: Mario Luzardo Fierro | N57: 46294 | O57: EV-013 | P57: Navegación por teclado incompleta | R57: No requerida
A58: PR-049 | B58: Accesibilidad | C58: Accesibilidad | D58: Orden de foco en formularios | E58: Formularios de acceso y registro | F58: Teclado | G58: Recorrer campos y acciones. | H58: Mantener orden lógico y sin saltos. | I58: Persisten ajustes menores en algunos componentes. | J58: Ejecutada | K58: Cumple parcialmente | L58: Highest | M58: Mario Luzardo Fierro | N58: 46294 | O58: EV-013 | P58: Navegación por teclado incompleta | Q58: DEF-003 | R58: Pendiente | S58: Corregir orden de foco y repetir antes del 02/10/2026.
...

Sheet Defectos y revalidación
A2: Defectos y revalidación
A3: Hallazgos derivados de resultados parciales. El cierre exige corrección, nueva ejecución y evidencia actualizada.
A6: Código | B6: Módulo | C6: Título | D6: Descripción | E6: Severidad | F6: Responsable | G6: Fecha compromiso | H6: Estado | I6: Caso relacionado | J6: Acción de revalidación
A7: DEF-001 | B7: Recuperación | C7: Validación integral incompleta | D7: Falta consolidar evidencia de token, caducidad y notificación. | E7: Media | F7: Luis Ramírez Conejo | G7: 46298 | H7: En corrección | I7: PR-028 | J7: Revalidar flujo completo.
A8: DEF-002 | B8: Roles y permisos | C8: Cobertura incompleta de roles | D8: La matriz y pruebas no incluyen todos los roles proyectados. | E8: Alta | F8: Kevin Carriel Bonoso | G8: 46297 | H8: En corrección | I8: PR-035 | J8: Ejecutar autorización por rol y acceso directo.
A9: DEF-003 | B9: Accesibilidad | C9: Orden de foco requiere ajustes | D9: Algunos componentes presentan recorrido de teclado mejorable. | E9: Media | F9: Mario Luzardo Fierro | G9: 46297 | H9: En corrección | I9: PR-049 | J9: Repetir prueba de teclado después del ajuste.
A10: DEF-004 | B10: Integración | C10: Regresión integral pendiente | D10: El flujo principal funciona, pero faltan escenarios secundarios. | E10: Alta | F10: Kevin Carriel Bonoso | G10: 46297 | H10: En corrección | I10: PR-064 | J10: Ejecutar smoke test y regresión completa.
A11: DEF-005 | B11: Auditoría | C11: Cobertura funcional incompleta | D11: Los logs no cubren todas las operaciones relevantes. | E11: Media | F11: Luis Ramírez Conejo | G11: 46298 | H11: En corrección | I11: PR-065 | J11: Confirmar fecha, usuario y evento sin datos sensibles.

Sheet Catálogos
A1: Estado ejecución | B1: Resultado | C1: Prioridad | D1: Responsable | E1: Revalidación | F1: Severidad | G1: Estado defecto
A2: Pendiente | B2: Cumple | C2: Highest | D2: Alex Mendoza Morante | E2: No requerida | F2: Crítica | G2: Abierto
A3: En ejecución | B3: Cumple parcialmente | C3: High | D3: Víctor Tello Bravo | E3: Pendiente | F3: Alta | G3: En corrección
A4: Ejecutada | B4: No cumple | C4: Low | D4: Kevin Carriel Bonoso | E4: Ejecutada conforme | F4: Media | G4: Pendiente de revalidación
A5: Bloqueada | B5: No evaluado | C5: Lowest | D5: Mario Luzardo Fierro | E5: Ejecutada no conforme | F5: Baja | G5: Cerrado
D6: Luis Ramírez Conejo | G6: Aceptado
D7: Luis Rodríguez Barrera
